Workbook

Sheet Centralizator
A3: CENTRALIZATOR OFERTA PAVILION V - INSTALATII
A6: Nr. | B6: Cod | C6: Denumire | D6: Valoare Oferta
A7: Crt. | B7: Deviz | C7: Lucrare/echipament/dotare | D7: Material | E7: Manopera | F7: Echipament | G7: TOTAL
A8: 1 | B8: O.03 D.00 | C8: ='O.03 D.00'!A5 -> Categorie: 00 INST.SANITARE-DEMONTARI | D8: ='O.03 D.00'!E43 -> 132 | E8: ='O.03 D.00'!F43 -> 24894.4 | G8: =SUM(D8:F8) -> 25026.4
A9: 2 | B9: O.03 D.01 | C9: ='O.03 D.01'!A5 -> Categorie: 01 INST.SANITARE INTERIOARE | D9: ='O.03 D.01'!E205 -> 226126.29 | E9: ='O.03 D.01'!F205 -> 123490.34 | G9: =SUM(D9:F9) -> 349616.63
A10: 3 | B10: O.03 D.02 | C10: ='O.03 D.02'!A5 -> Categorie: 02 INST.HIDRANTI INTERIORI | D10: ='O.03 D.02'!E54 -> 15696.48 | E10: ='O.03 D.02'!F54 -> 18158.992 | G10: =SUM(D10:F10) -> 33855.472
A11: 4 | B11: O.03 D.03 | C11: ='O.03 D.03'!A5 -> Categorie: 03 STATIE DE POMPARE INCENDIU | D11: ='O.03 D.03'!E99 -> 22135.83 | E11: ='O.03 D.03'!F99 -> 34680 | G11: =SUM(D11:F11) -> 56815.83
A12: 5 | B12: O.03 D.04 | C12: ='O.03 D.04'!A5 -> Categorie: 04 RETEA EXT.CANALIZARE MENAJERA | D12: ='O.03 D.04'!E42 -> 8669.6 | E12: ='O.03 D.04'!F42 -> 10504.72 | G12: =SUM(D12:F12) -> 19174.32
C13: F4 | F13: ='F4'!F31 -> 78549 | G13: =F13 -> 78549
A14: 6 | B14: O.04 D.01 | C14: ='O.04 D.01'!A5 -> Categorie: 01 INST.TERMICE RADIAT.+C.T. | D14: ='O.04 D.01'!E357 -> 303031.31 | E14: ='O.04 D.01'!F357 -> 185521.99 | G14: =SUM(D14:F14) -> 488553.3
C15: F4 | F15: ='F4'!F50 -> 153446 | G15: =F15 -> 153446
A16: 7 | B16: O.05 D.01 | C16: ='O.05 D.01'!A5 -> Categorie: 01 INST.CLIMATIZARE | D16: ='O.05 D.01'!E120 -> 115889.17 | E16: ='O.05 D.01'!F120 -> 106948.4 | G16: =SUM(D16:F16) -> 222837.57
A17: 8 | B17: O.05 D.02 | C17: ='O.05 D.02'!A5 -> Categorie: 02 INST.VENT.GR.SANIT.VAR.1 | D17: ='O.05 D.02'!E105 -> 18079 | E17: ='O.05 D.02'!F105 -> 14229 | G17: =SUM(D17:F17) -> 32308
C18: F4 | F18: ='F4'!F79 -> 0 | G18: =F18 -> 0
A19: TOTAL | D19: =SUM(D8:D18) -> 709759.67 | E19: =SUM(E8:E18) -> 518427.84 | F19: =SUM(F8:F18) -> 231995 | G19: =SUM(G8:G18) -> 1460182.5

Sheet F4
A1: Formular F4
A2: Obiectiv: UTCB REAB.,CONS.CFDP CORP C22-C.NOU
A3: LISTA_x000D_ cu cantitatile de utilaje si echipamente tehnologice, inclusiv dotari
G4: [ ron ]
A5: Nr. | B5: Cod | C5: U/M | D5: Cantitatea | E5: Pretul unitar | F5: Valoarea | G5: Fisa tehnica
A6: Crt. | B6: Denumirea | F6: (exclusiv TVA) | G6: atasata
A7: 1 | B7: Obiect 03 INST.SANITARE
B8: a) Utilaje, echipamente tehnologice si functionale care necesita montaj
B9: 1 | C9: BUCATA | D9: 1 | E9: 840 | F9: =D9*E9 -> 840 | G9: FT1
B10: CONTOR APA RECE
B11: 10 | C11: BUCATA | D11: 1 | E11: 334 | F11: =D11*E11 -> 334 | G11: FT10
B12: STINGATOR PORTATIV P3
B13: 11 | C13: BUCATA | D13: 1 | E13: 1870 | F13: =D13*E13 -> 1870 | G13: FT11
B14: PICHET PSI
B15: 2. | C15: BUCATA | D15: 1 | E15: 3850 | F15: =D15*E15 -> 3850 | G15: FT2
B16: POMPA SUBMERSIBILA CU PLUTITOR PENTRU BASA
B17: 3. | C17: BUCATA | D17: 5 | E17: 3250 | F17: =D17*E17 -> 16250 | G17: FT3
B18: STATIE DE COLECTARE SI POMPARE AUTOMATA
B19: 4. | C19: BUCATA | D19: 3 | E19: 2750 | F19: =D19*E19 -> 8250 | G19: FT4
B20: STATIE DE COLECTARE SI EVACUARE APE UZATE SI REZ DE UZ CASNI
B21: 5. | C21: BUCATA | D21: 1 | E21: 27580 | F21: =D21*E21 -> 27580 | G21: FT5
B22: GRUP POMPARE INCENDIU HIDR INT 1PA+1PP(TAB AUT INCLUS)
B23: 6 | C23: BUCATA | D23: 1 | E23: 750 | F23: =D23*E23 -> 750 | G23: FT6
B24: VAS EXPANSIUNE INCHIS,CU MEMBRANA. CAPACITATE 60L
B25: 7 | C25: BUCATA | D25: 14 | E25: 800 | F25: =D25*E25 -> 11200 | G25: FT7
B26: HIDRANT INTERIOR DE INCENDIU, COMPLET ECHIPAT
B27: 8 | C27: BUCATA | D27: 2 | E27: 1450 | F27: =D27*E27 -> 2900 | G27: FT8
B28: REZERVOR STOCARE APA INCENDIU. CAPACITATE 1000L
B29: 9 | C29: BUCATA | D29: 15 | E29: 315 | F29: =D29*E29 -> 4725 | G29: FT9
B30: STINGATOR PORTATIV CU PULBERE TIP P6
D31: Total obiect | F31: =ROUND($F$9+$F$11+$F$13+$F$15+$F$17+$F$19+$F$21+$F$23+$F$25+$F$27+$F$29,2) -> 78549
A32: 1 | B32: Obiect 04 INST.TERMICE
B33: a) Utilaje, echipamente tehnologice si functionale care necesita montaj
B34: 2.1 | C34: BUCATA | D34: 3 | E34: 27866 | F34: =D34*E34 -> 83598 | G34: FT1
B35: GRUP TERMIC MURAL 115KW, CONDENSATIE
B36: 2.2 | C36: BUCATA | D36: 3 | E36: 1750 | F36: =D36*E36 -> 5250 | G36: 5FT2
B37: VAS DE EXPANSIUNE 100LT
B38: 2.3 | C38: BUCATA | D38: 1 | E38: 6650 | F38: =D38*E38 -> 6650 | G38: FT3
B39: BOILER 500 LT PENTRU APA CALDA
B40: 2.4 | C40: BUCATA | D40: 1 | E40: 250 | F40: =D40*E40 -> 250 | G40: FT4
...

Sheet O.03 D.00
A1: Formular F3 | J1: 1
A2: Obiectiv: UTCB REAB.,CONS.CFDP CORP C22-C.NOU
A3: LISTA_x000D_ cu cantitatile de lucrari pe categorii de lucrari
A4: Obiect: 03 INST.SANITARE
A5: Categorie: 00 INST.SANITARE-DEMONTARI | I5: [ ron ]
B6: Nr. | C6: Capitol lucrari | D6: U/M | G6: Cantitatea | H6: Pretul unitar | I6: Valoare
B7: Crt. | C7: Simbol | H7: a)materiale
C8: Denumire resursa | H8: b)manopera
C9: Liste Anexe | H9: Total(a+b)
B10: 1 | C10: RPSA14A1 82 | D10: M | G10: 93 | H10: 0 | I10: =G10*H10 -> 0 | J10: 1
A11: DEMONTARE TEVI OTEL ZINC OBIEC SANIT 3/8-1 TOLI* | H11: 28 | I11: =G10*H11 -> 2604 | J11: 2
H12: 28 | I12: =I10+I11 -> 2604 | J12: 5
B13: 2 | C13: RPSA14B1 82 | D13: M | G13: 117 | H13: 0 | I13: =G13*H13 -> 0 | J13: 1
A14: DEMONTARE TEVI OTEL ZINC OBIEC SANIT 11/4-2 TOLI* | H14: 44.8 | I14: =G13*H14 -> 5241.6 | J14: 2
H15: 44.8 | I15: =I13+I14 -> 5241.6 | J15: 5
B16: 3 | C16: RPSB20A1 82 | D16: M | G16: 280 | H16: 0 | I16: =G16*H16 -> 0 | J16: 1
A17: DEMONTARE TUB FONTA CANALIZ 50 MM - 100 MM - asim. Demontare tub canalizare 40 mm | H17: 18.4 | I17: =G16*H17 -> 5152 | J17: 2
H18: 18.4 | I18: =I16+I17 -> 5152 | J18: 5
B19: 4 | C19: RPSC05A 99 | D19: BUCATA | G19: 45 | H19: 0 | I19: =G19*H19 -> 0 | J19: 1
A20: DEMONTAREA OBIECTELOR SANITARE | H20: 38.4 | I20: =G19*H20 -> 1728 | J20: 2
H21: 38.4 | I21: =I19+I20 -> 1728 | J21: 5
B22: 5 | C22: RPSD15A1 82 | D22: BUCATA | G22: 103 | H22: 0 | I22: =G22*H22 -> 0 | J22: 1
A23: DEMONTARE ROBINET PT. UTILIZARI MULTIPLE 3/8" - 1/2" | H23: 9.6 | I23: =G22*H23 -> 988.8 | J23: 2
H24: 9.6 | I24: =I22+I23 -> 988.8 | J24: 5
B25: 6 | C25: RPSF01A1 82 | D25: ZECI M | G25: 21 | H25: 0 | I25: =G25*H25 -> 0 | J25: 1
A26: GOLIREA INSTALATIEI DE APA IN VEDEREA EXECUTARII REPARATIILOR * | H26: 36 | I26: =G25*H26 -> 756 | J26: 2
H27: 36 | I27: =I25+I26 -> 756 | J27: 5
B28: 7 | C28: RPSF02B1 82 | D28: BUCATA | G28: 22 | H28: 6 | I28: =G28*H28 -> 132 | J28: 1
A29: BUSONAREA CONDUCTEI ALIMENTARE CU APA IN VEDEREA DESFIINTARII POZ OBIECTE ARMATURI DN 1/2" $ - DOP DIN FONTA MALEABILA T9 S487 DN 15 1/2 | H29: 12 | I29: =G28*H29 -> 264 | J29: 2
H30: 18 | I30: =I28+I29 -> 396 | J30: 5
B31: 8 | C31: RPSF09A1 82 | D31: M | G31: 17 | H31: 0 | I31: =G31*H31 -> 0 | J31: 1
A32: DESFUNDAREA CANALULUI COLECTOR CU MIJLOACE MANUALE IN CANTITATI DE PINA LA 5 M | H32: 144 | I32: =G31*H32 -> 2448 | J32: 2
H33: 144 | I33: =I31+I32 -> 2448 | J33: 5
B34: 9 | C34: IZJ12A1 82 | D34: MP | G34: 8.5 | H34: 0 | I34: =G34*H34 -> 0 | J34: 1
A35: DESFACEREA IZOLATIILOR TERMICE DE ORICE FEL $ | H35: 240 | I35: =G34*H35 -> 2040 | J35: 2
H36: 240 | I36: =I34+I35 -> 2040 | J36: 5
B37: 10 | C37: RPCT09H1 82 | D37: M CUB | G37: 3.4 | H37: 0 | I37: =G37*H37 -> 0 | J37: 1
A38: SPARGEREA PARTIALA CU MIJLOACE MEC SI MANUALA A ELEMENTELOR DE CONS.DIN BET.ARM.SI SIMPLU EXEC.FIN * | H38: 1080 | I38: =G37*H38 -> 3672 | J38: 2
H39: 0 | I39: =I37+I38 -> 3672 | J39: 5
B40: 11 | C40: RPCB06A1 82 | D40: M CUB | G40: 3.4 | H40: 0 | I40: =G40*H40 -> 0 | J40: 1
...

Sheet O.03 D.01
A1: Formular F3 | J1: 1
A2: Obiectiv: UTCB REAB.,CONS.CFDP CORP C22-C.NOU
A3: LISTA_x000D_ cu cantitatile de lucrari pe categorii de lucrari
A4: Obiect: 03 INST.SANITARE
A5: Categorie: 01 INST.SANITARE INTERIOARE | I5: [ ron ]
B6: Nr. | C6: Capitol lucrari | D6: U/M | G6: Cantitatea | H6: Pretul unitar | I6: Valoare
B7: Crt. | C7: Simbol | H7: a)materiale
C8: Denumire resursa | H8: b)manopera
C9: Liste Anexe | H9: Total(a+b)
B10: 1 | C10: SA03F 99 | D10: M | G10: 17 | H10: 75 | I10: =G10*H10 -> 1275 | J10: 1
A11: TEAVA DIN OTEL ZN PT. INSTALATII, MONTATA IN COLOANE, LA CLAD.DE LOCUIT SI SOCIAL CULTURALE, 2 " - TEAVA INST.ZINC FL+MF M - 50(2 ) OL 32 1 S 7656 | H11: 36 | I11: =G10*H11 -> 612 | J11: 2
H12: 111 | I12: =I10+I11 -> 1887 | J12: 5
B13: 2 | C13: RPIF12A 99 | D13: M | G13: 17 | H13: 43 | I13: =G13*H13 -> 731 | J13: 1
A14: GRUNDUIREA SI VOPSIREA CONDUCTELOR DE INSTALATII,2 STRATURI,VOPSEA ULEI,DIAMETRUL EXTERIOR < 60 MM | H14: 22.36 | I14: =G13*H14 -> 380.12 | J14: 2
H15: 65.36 | I15: =I13+I14 -> 1111.12 | J15: 5
B16: 3 | C16: RPIZD02A 99 | D16: MP | G16: 5 | H16: 40 | I16: =G16*H16 -> 200 | J16: 1
A17: IZOL COND CU SALTELE DIN VATA STICL SAU MIN TIP I SAU P CONF SANT CU CIRC PESTE TERMOIZ < 35CM INCL | H17: 12 | I17: =G16*H17 -> 60 | J17: 2
H18: =H17+H16 -> 52 | I18: =I16+I17 -> 260 | J18: 5
B19: 4 | C19: IC40E 99 | D19: BUCATA | G19: 12 | H19: 18 | I19: =G19*H19 -> 216 | J19: 1
A20: BRATARA PT.FIXARE COND.OL PT.INST.INC.CENTR.SAU GAZE D=11/4-2" MONT.PRIN DIBLURI EXP PE ZID BETON -BRATARI TEVI INSTALATII APA SI GAZE 2" | H20: 9.36 | I20: =G19*H20 -> 112.32 | J20: 2
H21: 27.36 | I21: =I19+I20 -> 328.32 | J21: 5
B22: 5 | C22: SA14B 99 | D22: M | G22: 552 | H22: 53 | I22: =G22*H22 -> 29256 | J22: 1
A23: TEAVA DIN MATERIAL PLASTIC(PE,PP,PP-R,SIMILAR),SUDURA PRIN POLIFUZIUNE,CONSTRUCTII IND, D=20MM -Teava din polipropilena compozita avand Dn 20x2,8 mm | H23: 25.44 | I23: =G22*H23 -> 14042.88 | J23: 2
H24: 78.44 | I24: =I22+I23 -> 43298.88 | J24: 5
B25: 6 | C25: SA14C 99 | D25: M | G25: 42 | H25: 55 | I25: =G25*H25 -> 2310 | J25: 1
A26: TEAVA DIN MATERIAL PLASTIC(PE,PP,PP-R,SIMILAR),SUDURA PRIN POLIFUZIUNE,CONSTRUCTII IND, D=25MM - Teava din polipropilena compozita avand Dn 25x3,5 mm | H26: 28.6 | I26: =G25*H26 -> 1201.2 | J26: 2
H27: 83.6 | I27: =I25+I26 -> 3511.2 | J27: 5
B28: 7 | C28: SA14D 99 | D28: M | G28: 102 | H28: 64 | I28: =G28*H28 -> 6528 | J28: 1
A29: TEAVA DIN MATERIAL PLASTIC(PE,PP,PP-R,SIMILAR),SUDURA PRIN POLIFUZIUNE,CONSTRUCTII IND, D=32MM - Teava din polipropilena compozita avand Dn 32x4,4 mm | H29: 30.72 | I29: =G28*H29 -> 3133.44 | J29: 2
H30: 94.72 | I30: =I28+I29 -> 9661.44 | J30: 5
B31: 8 | C31: SA14E 99 | D31: M | G31: 25 | H31: 75 | I31: =G31*H31 -> 1875 | J31: 1
A32: TEAVA DIN MATERIAL PLASTIC(PE,PP,PP-R,SIMILAR),SUDURA PRIN POLIFUZIUNE,CONSTRUCTII IND, D=40MM - Teava din polipropilena compozita avand Dn 40x5,5 mm | H32: 39 | I32: =G31*H32 -> 975 | J32: 2
H33: 114 | I33: =I31+I32 -> 2850 | J33: 5
B34: 9 | C34: SA14F 99 | D34: M | G34: 17 | H34: 86 | I34: =G34*H34 -> 1462 | J34: 1
A35: TEAVA DIN MATERIAL PLASTIC(PE,PP,PP-R,SIMILAR),SUDURA PRIN POLIFUZIUNE,CONSTRUCTII IND, D=50MM, PP-R ALBA CU FIBRA PN20 SDR 7,4 D.50X6,9MM L=3M | H35: 41.28 | I35: =G34*H35 -> 701.76 | J35: 2
H36: 127.28 | I36: =I34+I35 -> 2163.76 | J36: 5
B37: 10 | C37: SA14G 99 | D37: M | G37: 8 | H37: 94 | I37: =G37*H37 -> 752 | J37: 1
A38: TEAVA DIN MATERIAL PLASTIC(PE,PP,PP-R,SIMILAR),SUDURA PRIN POLIFUZIUNE,CONSTRUCTII IND, D=63MM, PP-R ALBA CU FIBRA PN20 SDR 7,4 D.63X8,6MM L=3M | H38: 48.88 | I38: =G37*H38 -> 391.04 | J38: 2
H39: 142.88 | I39: =I37+I38 -> 1143.04 | J39: 5
B40: 11 | C40: IZD07A 09 | D40: M | G40: 552 | H40: 14 | I40: =G40*H40 -> 7728 | J40: 1
...

Sheet O.03 D.02
A1: Formular F3 | J1: 1
A2: Obiectiv: UTCB REAB.,CONS.CFDP CORP C22-C.NOU
A3: LISTA_x000D_ cu cantitatile de lucrari pe categorii de lucrari
A4: Obiect: 03 INST.SANITARE
A5: Categorie: 02 INST.HIDRANTI INTERIORI | I5: [ ron ]
B6: Nr. | C6: Capitol lucrari | D6: U/M | G6: Cantitatea | H6: Pretul unitar | I6: Valoare
B7: Crt. | C7: Simbol | H7: a)materiale
C8: Denumire resursa | H8: b)manopera
C9: Observatii | H9: c)utilaj
C10: Corectii | H10: d)transport
C11: Liste Anexe | H11: Total(a+b+c+d)
B12: 1 | C12: SA03F 99 | D12: M | G12: 102 | H12: 90 | I12: =G12*H12 -> 9180 | J12: 1
A13: TEAVA DIN OTEL ZN PT. INSTALATII, MONTATA IN COLOANE, LA CLAD.DE LOCUIT SI SOCIAL CULTURALE, 2 " , TEAVA INST.ZINC FL+MF M - 50(2 ) OL 32 1 S 7656 | H13: 61.2 | I13: =G12*H13 -> 6242.4 | J13: 2
H14: 151.2 | I14: =I12+I13 -> 15422.4 | J14: 5
B15: 2 | C15: SA38F 99 | D15: BUCATA | G15: 80 | H15: 21.6 | I15: =G15*H15 -> 1728 | J15: 1
A16: BRATARA PT.FIXAREA COND.DE ALIM.CU APA SI GAZE,OTEL SAU PVC ,MONTATA PRIN IMPUSCARE, D= 2" , BRATARI TEVI INSTALATII APA SI GAZE | H16: 13.6 | I16: =G15*H16 -> 1088 | J16: 2
H17: 35.2 | I17: =I15+I16 -> 2816 | J17: 5
B18: 3 | C18: SA35A 99 | D18: BUCATA | G18: 17 | H18: 61.2 | I18: =G18*H18 -> 1040.4 | J18: 1
A19: FITINGURI-FONTA MALEABILA,INSURUBARE,LA TEVILE DIN OTEL PT.INSTAL-ZINCATE,IN COL.PT.HIDRANTI INTR,2" , Mufa din fonta maleabila D=2" | H19: 40.8 | I19: =G18*H19 -> 693.6 | J19: 2
H20: 102 | I20: =I18+I19 -> 1734 | J20: 5
B21: 4 | C21: SA35A 99 | D21: BUCATA | G21: 42 | H21: 61.2 | I21: =G21*H21 -> 2570.4 | J21: 1
A22: FITINGURI-FONTA MALEABILA,INSURUBARE,LA TEVILE DIN OTEL PT.INSTAL-ZINCATE,IN COL.PT.HIDRANTI INTR,2" , COT FONTA MALEABILA A1 | H22: 40.8 | I22: =G21*H22 -> 1713.6 | J22: 2
H23: 102 | I23: =I21+I22 -> 4284 | J23: 5
B24: 5 | C24: SA35A 99 | D24: BUCATA | G24: 12 | H24: 61.2 | I24: =G24*H24 -> 734.4 | J24: 1
A25: FITINGURI-FONTA MALEABILA,INSURUBARE,LA TEVILE DIN OTEL PT.INSTAL-ZINCATE,IN COL.PT.HIDRANTI INTR,2", TEU FONTA MAL B1 S476 DN= 50 | H25: 40.8 | I25: =G24*H25 -> 489.6 | J25: 2
H26: 102 | I26: =I24+I25 -> 1224 | J26: 5
B27: 6 | C27: SD17B 99 | D27: BUCATA | G27: 14 | H27: 0 | I27: =G27*H27 -> 0 | J27: 1
A28: HIDRANT INTERIOR, PENTRU CLADIRI, CU DIAMETRUL DE 2", PE PERETE (CUTIE+RAMA) | H28: 516.8 | I28: =G27*H28 -> 7235.2 | J28: 2
H29: 516.8 | I29: =I27+I28 -> 7235.2 | J29: 5
B30: 7 | C30: SA04A 99 | D30: M | G30: 2 | H30: 31.2 | I30: =G30*H30 -> 62.4 | J30: 1
A31: TEAVA DIN OTEL ZN PT. INSTALATII, MONTATA IN COND.DISTRIB, LA CLAD.DE LOCUIT SI SOCIAL CULT, 1/2 " , TEAVA INST.ZINC FL+MF M - 15( 1/2) OL | H31: 20.4 | I31: =G30*H31 -> 40.8 | J31: 2
H32: 51.6 | I32: =I30+I31 -> 103.2 | J32: 5
B33: 8 | C33: SA38A 99 | D33: BUCATA | G33: 2 | H33: 10.8 | I33: =G33*H33 -> 21.6 | J33: 1
A34: BRATARA PT.FIXAREA COND.DE ALIM.CU APA SI GAZE,OTEL SAU PVC ,MONTATA PRIN IMPUSCARE, D= 1/2" | H34: 6.8 | I34: =G33*H34 -> 13.6 | J34: 2
H35: 17.6 | I35: =I33+I34 -> 35.2 | J35: 5
B36: 9 | C36: SA35A 99 | D36: BUCATA | G36: 1 | H36: 61.2 | I36: =G36*H36 -> 61.2 | J36: 1
A37: FITINGURI-FONTA MALEABILA,INSURUBARE,LA TEVILE DIN OTEL PT.INSTAL-ZINCATE,IN COL.PT.HIDRANTI INTR,2" , Teu din fonta maleabila 2"-1/2"-2" | H37: 40.8 | I37: =G36*H37 -> 40.8 | J37: 2
H38: 102 | I38: =I36+I37 -> 102 | J38: 5
B39: 10 | C39: SD07A 99 | D39: BUCATA | G39: 1 | H39: 38.4 | I39: =G39*H39 -> 38.4 | J39: 1
A40: ROBINET DE TRECERE CU VENTIL SI MUFE, CU SAU FARA DESCARCARE,PT.TEVI DIN OTEL, D=3/8-1/2" , ROBINET TREC. FONTA 1/2" A VENT+MUFA PN10 | H40: 25.84 | I40: =G39*H40 -> 25.84 | J40: 2
...

Sheet O.03 D.03
A1: Formular F3 | J1: 1
A2: Obiectiv: UTCB REAB.,CONS.CFDP CORP C22-C.NOU
A3: LISTA_x000D_ cu cantitatile de lucrari pe categorii de lucrari
A4: Obiect: 03 INST.SANITARE
A5: Categorie: 03 STATIE DE POMPARE INCENDIU | I5: [ ron ]
B6: Nr. | C6: Capitol lucrari | D6: U/M | G6: Cantitatea | H6: Pretul unitar | I6: Valoare
B7: Crt. | C7: Simbol | H7: a)materiale
C8: Denumire resursa | H8: b)manopera
C9: Observatii | H9: c)utilaj
C10: Corectii | H10: d)transport
C11: Liste Anexe | H11: Total(a+b+c+d)
B12: 1 | C12: SA04C 99 | D12: M | G12: 12 | H12: 37.5 | I12: =G12*H12 -> 450 | J12: 1
A13: TEAVA DIN OTEL ZN PT. INSTALATII, MONTATA IN COND.DISTRIB, LA CLAD.DE LOCUIT SI SOCIAL CULT, 1 " , TEAVA INST.ZINC FL+MF M - 25(1 ) OL 32 | H13: 29.92 | I13: =G12*H13 -> 359.04 | J13: 2
H14: 67.42 | I14: =I12+I13 -> 809.04 | J14: 5
B15: 2 | C15: SA04F 99 | D15: M | G15: 17 | H15: 75 | I15: =G15*H15 -> 1275 | J15: 1
A16: TEAVA DIN OTEL ZN PT. INSTALATII, MONTATA IN COND.DISTRIB, LA CLAD.DE LOCUIT SI SOCIAL CULT, 2 " , TEAVA INST.ZINC FL+MF M - 50(2 ) OL 32 | H16: 61.2 | I16: =G15*H16 -> 1040.4 | J16: 2
H17: 136.2 | I17: =I15+I16 -> 2315.4 | J17: 5
B18: 3 | C18: SA04E 99 | D18: M | G18: 8 | H18: 56.25 | I18: =G18*H18 -> 450 | J18: 1
A19: TEAVA DIN OTEL ZN PT. INSTALATII, MONTATA IN COND.DISTRIB, LA CLAD.DE LOCUIT SI SOCIAL CULT, 1 1/2 " , TEAVA INST.ZINC FL+MF M - 40(1 1/2) OL 32 | H19: 44.88 | I19: =G18*H19 -> 359.04 | J19: 2
H20: 101.13 | I20: =I18+I19 -> 809.04 | J20: 5
B21: 4 | C21: SA41C2 82 | D21: BUCATA | G21: 17 | H21: 99.99 | I21: =G21*H21 -> 1699.83 | J21: 1
A22: FLANSA ROTUNDA PLATA,PT.SUDARE,LA CONDUCTE DIN TEAVA NEAGRA DE OTEL PT.INSTAL,PN 6;10;16ATM,D= 50MM | H22: 80.24 | I22: =G21*H22 -> 1364.08 | J22: 2
H23: 180.23 | I23: =I21+I22 -> 3063.91 | J23: 5
B24: 5 | C24: SA38C 99 | D24: BUCATA | G24: 12 | H24: 13 | I24: =G24*H24 -> 156 | J24: 1
A25: BRATARA PT.FIXAREA COND.DE ALIM.CU APA SI GAZE,OTEL SAU PVC ,MONTATA PRIN IMPUSCARE, D= 1" | H25: 9.52 | I25: =G24*H25 -> 114.24 | J25: 2
H26: 22.52 | I26: =I24+I25 -> 270.24 | J26: 5
B27: 6 | C27: SA38E 99 | D27: BUCATA | G27: 8 | H27: 16 | I27: =G27*H27 -> 128 | J27: 1
A28: BRATARA PT.FIXAREA COND.DE ALIM.CU APA SI GAZE,OTEL SAU PVC ,MONTATA PRIN IMPUSCARE, D= 1 1/2" | H28: 12.24 | I28: =G27*H28 -> 97.92 | J28: 2
H29: 28.24 | I29: =I27+I28 -> 225.92 | J29: 5
B30: 7 | C30: SA38F 99 | D30: BUCATA | G30: 17 | H30: 18 | I30: =G30*H30 -> 306 | J30: 1
A31: BRATARA PT.FIXAREA COND.DE ALIM.CU APA SI GAZE,OTEL SAU PVC ,MONTATA PRIN IMPUSCARE, D= 2" | H31: 13.6 | I31: =G30*H31 -> 231.2 | J31: 2
H32: 31.6 | I32: =I30+I31 -> 537.2 | J32: 5
B33: 8 | C33: SA35A 99 | D33: BUCATA | G33: 17 | H33: 51 | I33: =G33*H33 -> 867 | J33: 1
A34: FITINGURI-FONTA MALEABILA,INSURUBARE,LA TEVILE DIN OTEL PT.INSTAL-ZINCATE,IN COL.PT.HIDRANTI INTR,2", COT FONTA MALEABILA A1 | H34: 40.8 | I34: =G33*H34 -> 693.6 | J34: 2
H35: 91.8 | I35: =I33+I34 -> 1560.6 | J35: 5
B36: 9 | C36: SA35A 99 | D36: BUCATA | G36: 2 | H36: 51 | I36: =G36*H36 -> 102 | J36: 1
A37: FITINGURI-FONTA MALEABILA,INSURUBARE,LA TEVILE DIN OTEL PT.INSTAL-ZINCATE,IN COL.PT.HIDRANTI INTR,2", TEU FONTA MAL B1 S476 DN= 50 | H37: 40.8 | I37: =G36*H37 -> 81.6 | J37: 2
H38: 91.8 | I38: =I36+I37 -> 183.6 | J38: 5
B39: 10 | C39: SA35A 99 | D39: BUCATA | G39: 2 | H39: 36 | I39: =G39*H39 -> 72 | J39: 1
A40: FITINGURI-FONTA MALEABILA,INSURUBARE,LA TEVILE DIN OTEL PT.INSTAL-ZINCATE,IN COL.PT.HIDRANTI INTR,2", REDUCTIE FONTA MALEABILA N4 S 477 50X 40 ZN F2 | H40: 28.56 | I40: =G39*H40 -> 57.12 | J40: 2
...

Sheet O.03 D.04
A1: Formular F3 | J1: 1
A2: Obiectiv: UTCB REAB.,CONS.CFDP CORP C22-C.NOU
A3: LISTA_x000D_ cu cantitatile de lucrari pe categorii de lucrari
A4: Obiect: 03 INST.SANITARE
A5: Categorie: 04 RETEA EXT.CANALIZARE MENAJERA | I5: [ ron ]
B6: Nr. | C6: Capitol lucrari | D6: U/M | G6: Cantitatea | H6: Pretul unitar | I6: Valoare
B7: Crt. | C7: Simbol | H7: a)materiale
C8: Denumire resursa | H8: b)manopera
C9: Observatii | H9: c)utilaj
C10: Corectii | H10: d)transport
C11: Liste Anexe | H11: Total(a+b+c+d)
B12: 1 | C12: ACD01G1 82 | D12: BUCATA | G12: 1 | H12: 700 | I12: =G12*H12 -> 700 | J12: 1
A13: CAPAC SI RAMA STAS 2308-81 PENTRU CAMINE CU PIESA SUPORT NECAROSABIL TIP I $ | H13: 571.2 | I13: =G12*H13 -> 571.2 | J13: 2
H14: 1036 | I14: =I12+I13 -> 1271.2 | J14: 5
B15: 2 | C15: RPACF14E 99 | D15: BUCATA | G15: 1 | H15: 4930 | I15: =G15*H15 -> 4930 | J15: 1
A16: CAMINE DE VIZITARE CU H=2 M, SECTIUNEA CIRCULARA, D = 1000 MM | H16: 1392 | I16: =G15*H16 -> 1392 | J16: 2
H17: 7296.4 | I17: =I15+I16 -> 6322 | J17: 5
B18: 3 | C18: ACD18B 99 | D18: M | G18: 51 | H18: 46 | I18: =G18*H18 -> 2346 | J18: 1
A19: MONTAREA TV. PVC TIP M-3 PT.SCURGERE,IMB.LIPIRE,INEXT.CLADIRILOR, LA 2 M ADANC. D = 75 - 125 MM , TEAVA PVC CU MUFA SI GARNIT. SN4/SDR41 D=110X3,2MM L=1M | H19: 36.72 | I19: =G18*H19 -> 1872.72 | J19: 2
H20: 67.6 | I20: =I18+I19 -> 4218.72 | J20: 5
B21: 4 | C21: DF15XA 93 | D21: M | G21: 34 | H21: 20.4 | I21: =G21*H21 -> 693.6 | J21: 1
A22: MARCAJ LONGITUDINAL CU BANDA DIN MATERIAL TERMOPLASTIC REFLECTORIZANT, BANDA DIN MATERIAL TERMOPLASTIC REFLECTORIZANTA | H22: 3.2 | I22: =G21*H22 -> 108.8 | J22: 2
H23: 25.84 | I23: =I21+I22 -> 802.4 | J23: 5
B24: 5 | C24: RPCA01B1 82 | D24: M CUB | G24: 24 | H24: 0 | I24: =G24*H24 -> 0 | J24: 1
A25: SAPATURA DE PAMINT IN SPATII LIMITATE SUB 1,00 M LATIME SI 1,50 M ADINCIME CU MALURI SPRIJINITE * | H25: 0 | I25: =G24*H25 -> 0 | J25: 2
H26: 0 | I26: =I24+I25 -> 0 | J26: 5
B27: 6 | C27: ACE08A1 82 | D27: M CUB | G27: 10 | H27: 0 | I27: =G27*H27 -> 0 | J27: 1
A28: UMPLUTURA IN SANT.LA COND.DE ALIM.CU APA SI CANALIZARE CU: NISIP $ | H28: 640 | I28: =G27*H28 -> 6400 | J28: 2
H29: 1088 | I29: =I27+I28 -> 6400 | J29: 5
B30: 7 | C30: TSD01C1 82 | D30: M CUB | G30: 14 | H30: 0 | I30: =G30*H30 -> 0 | J30: 1
A31: IMPRASTIEREA CU LOPATA A PAMINT.AFINAT,STRAT UNIFORM 10-30CM.GROS CU SFARIM.BULG.TEREN TARE | H31: 0 | I31: =G30*H31 -> 0 | J31: 2
H32: 0 | I32: =I30+I31 -> 0 | J32: 5
B33: 8 | C33: TSD04C1 82 | D33: M CUB | G33: 14 | H33: 0 | I33: =G33*H33 -> 0 | J33: 1
A34: COMPACTAREA CU MAI.DE MINA A UMPLUT.EXECUT.PE STRAT.CU UDAREA FIEC.STRAT DE 20CM GROS.T.NECOEZIV | H34: 0 | I34: =G33*H34 -> 0 | J34: 2
H35: 0 | I35: =I33+I34 -> 0 | J35: 5
B36: 9 | C36: TSD13A1 82 | D36: M CUB | G36: 1.4 | H36: 0 | I36: =G36*H36 -> 0 | J36: 1
A37: UDAREA MAN.CU STROPIT.A STRATURILOR DE PAM.SI A SUPRAF.INSAMINTATE SAU BRAZDUITE | H37: 0 | I37: =G36*H37 -> 0 | J37: 2
H38: 0 | I38: =I36+I37 -> 0 | J38: 5
B39: 10 | C39: SF04B 99 | D39: ZECI M | G39: 5 | H39: 0 | I39: =G39*H39 -> 0 | J39: 1
A40: EFECTUAREA PROBEI DE ETANSEITATE SI FUCTIONARE A INSTALATIEI DE CANALIZARE(INDIFERENT MAT.),D=>100MM | H40: 32 | I40: =G39*H40 -> 160 | J40: 2
...

Sheet O.04 D.01
A1: Formular F3 | J1: 1
A2: Obiectiv: UTCB REAB.,CONS.CFDP CORP C22-C.NOU
A3: LISTA_x000D_ cu cantitatile de lucrari pe categorii de lucrari
A4: Obiect: 04 INST.TERMICE
A5: Categorie: 01 INST.TERMICE RADIAT.+C.T. | I5: [ ron ]
B6: Nr. | C6: Capitol lucrari | D6: U/M | G6: Cantitatea | H6: Pretul unitar | I6: Valoare
B7: Crt. | C7: Simbol | H7: a)materiale
C8: Denumire resursa | H8: b)manopera
C9: Observatii | H9: c)utilaj
C10: Corectii | H10: d)transport
C11: Liste Anexe | H11: Total(a+b+c+d)
B12: 1 | C12: IB06C 99 | D12: BUCATA | G12: 7 | H12: 740 | I12: =G12*H12 -> 5180 | J12: 1
A13: RADIATOARE DIN OTEL, MONOBLOC AVAND LUNGIMEA DE 1501 -2000 MM , Radiator monobloc de otel 22/600/2000, tip ECORAD | H13: 355.2 | I13: =G12*H13 -> 2486.4 | J13: 2
H14: 1095.2 | I14: =I12+I13 -> 7666.4 | J14: 5
B15: 2 | C15: IB06C 99 | D15: BUCATA | G15: 11 | H15: 555 | I15: =G15*H15 -> 6105 | J15: 1
A16: RADIATOARE DIN OTEL, MONOBLOC AVAND LUNGIMEA DE 1501 -2000 MM, Radiator monobloc de otel 22/600/1600 | H16: 266.4 | I16: =G15*H16 -> 2930.4 | J16: 2
H17: 821.4 | I17: =I15+I16 -> 9035.4 | J17: 5
B18: 3 | C18: IB06B 99 | D18: BUCATA | G18: 37 | H18: 495 | I18: =G18*H18 -> 18315 | J18: 1
A19: RADIATOARE DIN OTEL, MONOBLOC AVAND LUNGIMEA DE 1001 -1500 MM , Radiator monobloc de otel 22/600/1400 | H19: 237.6 | I19: =G18*H19 -> 8791.2 | J19: 2
H20: 732.6 | I20: =I18+I19 -> 27106.2 | J20: 5
B21: 4 | C21: IB06B 99 | D21: BUCATA | G21: 17 | H21: 428 | I21: =G21*H21 -> 7276 | J21: 1
A22: RADIATOARE DIN OTEL, MONOBLOC AVAND LUNGIMEA DE 1001 -1500 MM , Radiator monobloc de otel 22/600/1200 | H22: 205.44 | I22: =G21*H22 -> 3492.48 | J22: 2
H23: 633.44 | I23: =I21+I22 -> 10768.48 | J23: 5
B24: 5 | C24: IB06B 99 | D24: BUCATA | G24: 6 | H24: 344 | I24: =G24*H24 -> 2064 | J24: 1
A25: RADIATOARE DIN OTEL, MONOBLOC AVAND LUNGIMEA DE 1001 -1500 MM, Radiator monobloc de otel 22/600/1100 | H25: 229.33333 | I25: =G24*H25 -> 1376 | J25: 2
H26: =H25+H24 -> 573.33333 | I26: =I24+I25 -> 3440 | J26: 5
B27: 6 | C27: IB06A 99 | D27: BUCATA | G27: 12 | H27: 403 | I27: =G27*H27 -> 4836 | J27: 1
A28: RADIATOARE DIN OTEL, MONOBLOC AVAND LUNGIMEA DE PANA LA 1000 MM, INCLUSIV, Radiator monobloc de otel 22/600/1000 | H28: 268.66667 | I28: =G27*H28 -> 3224 | J28: 2
H29: =H28+H27 -> 671.66667 | I29: =I27+I28 -> 8060 | J29: 5
B30: 7 | C30: IB06A 99 | D30: BUCATA | G30: 6 | H30: 327 | I30: =G30*H30 -> 1962 | J30: 1
A31: RADIATOARE DIN OTEL, MONOBLOC AVAND LUNGIMEA DE PANA LA 1000 MM, INCLUSIV , Radiator monobloc de otel 22/600/900 | H31: 156.96 | I31: =G30*H31 -> 941.76 | J31: 2
H32: 483.96 | I32: =I30+I31 -> 2903.76 | J32: 5
B33: 8 | C33: IB06A 99 | D33: BUCATA | G33: 8 | H33: 319 | I33: =G33*H33 -> 2552 | J33: 1
A34: RADIATOARE DIN OTEL, MONOBLOC AVAND LUNGIMEA DE PANA LA 1000 MM, INCLUSIV , Radiator monobloc de otel 22/600/800 | H34: 153.12 | I34: =G33*H34 -> 1224.96 | J34: 2
H35: 472.12 | I35: =I33+I34 -> 3776.96 | J35: 5
B36: 9 | C36: IB06A 99 | D36: BUCATA | G36: 10 | H36: 243 | I36: =G36*H36 -> 2430 | J36: 1
A37: RADIATOARE DIN OTEL, MONOBLOC AVAND LUNGIMEA DE PANA LA 1000 MM, INCLUSIV, Radiator monobloc de otel 22/600/600 | H37: 116.64 | I37: =G36*H37 -> 1166.4 | J37: 2
H38: 359.64 | I38: =I36+I37 -> 3596.4 | J38: 5
B39: 10 | C39: IB06A 99 | D39: BUCATA | G39: 1 | H39: 235 | I39: =G39*H39 -> 235 | J39: 1
A40: RADIATOARE DIN OTEL, MONOBLOC AVAND LUNGIMEA DE PANA LA 1000 MM, INCLUSIV , Radiator monobloc de otel 11/600/1000, tip ECORAD | H40: 112.8 | I40: =G39*H40 -> 112.8 | J40: 2
...

Sheet O.05 D.01
A1: Formular F3 | J1: 1
A2: Obiectiv: UTCB REAB.,CONS.CFDP CORP C22-C.NOU
A3: LISTA_x000D_ cu cantitatile de lucrari pe categorii de lucrari
A4: Obiect: 05 INST.VENTILATII+CLIMATIZARE
A5: Categorie: 01 INST.CLIMATIZARE | I5: [ ron ]
B6: Nr. | C6: Capitol lucrari | D6: U/M | G6: Cantitatea | H6: Pretul unitar | I6: Valoare
B7: Crt. | C7: Simbol | H7: a)materiale
C8: Denumire resursa | H8: b)manopera
C9: Observatii | H9: c)utilaj
C10: Corectii | H10: d)transport
C11: Liste Anexe | H11: Total(a+b+c+d)
B12: 1 | C12: IC33D 99 | D12: M | G12: 93 | H12: 191.66667 | I12: =G12*H12 -> 17825 | J12: 1
A13: TEAVA DIN CUPRU DEXT=35MM MONT.PRIN SUDURA IN COND.DE DISTRIB.IN INST.DE INC.CENTRALA, Conducta cupru 34.9 mm pentru climatizare | H13: 92 | I13: =G12*H13 -> 8556 | J13: 2
H14: 283.66667 | I14: =I12+I13 -> 26381 | J14: 5
B15: 2 | C15: IC31D 99 | D15: M | G15: 46 | H15: 141.66667 | I15: =G15*H15 -> 6516.6667 | J15: 1
A16: TEAVA DIN CUPRU DEXT=28MM MONT.PRIN SUDURA LA LEG.CORP.INC. IN INST.DE INC.CENTRALA, Conducta cupru 28.6 mm pentru climatizare | H16: 68 | I16: =G15*H16 -> 3128 | J16: 2
H17: 209.66667 | I17: =I15+I16 -> 9644.6667 | J17: 5
B18: 3 | C18: IC31C 99 | D18: M | G18: 42 | H18: 108.33333 | I18: =G18*H18 -> 4550 | J18: 1
A19: TEAVA DIN CUPRU DEXT=22MM MONT.PRIN SUDURA LA LEG.CORP.INC. IN INST.DE INC.CENTRALA , Conducta cupru 22.2 mm pentru climatizare | H19: 52 | I19: =G18*H19 -> 2184 | J19: 2
H20: 160.33333 | I20: =I18+I19 -> 6734 | J20: 5
B21: 4 | C21: IC31B 99 | D21: M | G21: 80 | H21: 66.666667 | I21: =G21*H21 -> 5333.3333 | J21: 1
A22: TEAVA DIN CUPRU DEXT=18MM MONT.PRIN SUDURA LA LEG.CORP.INC. IN INST.DE INC.CENTRALA, Conducta cupru 19.1 mm pentru climatizare | H22: 32 | I22: =G21*H22 -> 2560 | J22: 2
H23: 98.666667 | I23: =I21+I22 -> 7893.3333 | J23: 5
B24: 5 | C24: IC31A 99 | D24: M | G24: 229 | H24: 50 | I24: =G24*H24 -> 11450 | J24: 1
A25: TEAVA DIN CUPRU DEXT<15MM MONT.PRIN SUDURA LA LEG.CORP.INC. IN INST.DE INC.CENTRALA, Conducta cupru 15.9 mm pentru climatizare | H25: 24 | I25: =G24*H25 -> 5496 | J25: 2
H26: 74 | I26: =I24+I25 -> 16946 | J26: 5
B27: 6 | C27: IC31A 99 | D27: M | G27: 255 | H27: 38.333333 | I27: =G27*H27 -> 9775 | J27: 1
A28: TEAVA DIN CUPRU DEXT<15MM MONT.PRIN SUDURA LA LEG.CORP.INC. IN INST.DE INC.CENTRALA, Conducta cupru 12.7 mm pentru climatizare | H28: 18.4 | I28: =G27*H28 -> 4692 | J28: 2
H29: 56.733333 | I29: =I27+I28 -> 14467 | J29: 5
B30: 7 | C30: IC31A 99 | D30: M | G30: 170 | H30: 26.666667 | I30: =G30*H30 -> 4533.3333 | J30: 1
A31: TEAVA DIN CUPRU DEXT<15MM MONT.PRIN SUDURA LA LEG.CORP.INC. IN INST.DE INC.CENTRALA, Conducta cupru 9.52 mm pentru climatizare | H31: 12.8 | I31: =G30*H31 -> 2176 | J31: 2
H32: 39.466667 | I32: =I30+I31 -> 6709.3333 | J32: 5
B33: 8 | C33: IC31A 99 | D33: M | G33: 272 | H33: 15 | I33: =G33*H33 -> 4080 | J33: 1
A34: TEAVA DIN CUPRU DEXT<15MM MONT.PRIN SUDURA LA LEG.CORP.INC. IN INST.DE INC.CENTRALA , Conducta cupru 6.35 mm pentru climatizare | H34: 7.2 | I34: =G33*H34 -> 1958.4 | J34: 2
H35: 22.2 | I35: =I33+I34 -> 6038.4 | J35: 5
B36: 9 | C36: IC34C 99 | D36: BUCATA | G36: 98 | H36: 41.666667 | I36: =G36*H36 -> 4083.3333 | J36: 1
A37: PIESE DE LEGATURA (FITING) DIN CUPRU CU 2 SUDURI D=22 MM MONT.PRIN SUDURA CU TV.DE CUPRU | H37: 20 | I37: =G36*H37 -> 1960 | J37: 2
H38: 61.666667 | I38: =I36+I37 -> 6043.3333 | J38: 5
B39: 10 | C39: IZD07A 09 | D39: M | G39: 1190 | H39: 3.3333333 | I39: =G39*H39 -> 3966.6667 | J39: 1
A40: IZOLARE TUBURI (TEVI) POLIETILENA DIN PERETI SI PARDOSEALA CU IZOLATIE TIP TUBOLIT S, Izolatie 9 mm grosime pentru trasee frigorifice cu diametrul 6.35 - 34.9 mm | H40: 1.6 | I40: =G39*H40 -> 1904 | J40: 2
...

Sheet O.05 D.02
A1: Formular F3 | J1: 1
A2: Obiectiv: UTCB REAB.,CONS.CFDP CORP C22-C.NOU
A3: LISTA_x000D_ cu cantitatile de lucrari pe categorii de lucrari
A4: Obiect: 05 INST.VENTILATII+CLIMATIZARE
A5: Categorie: 02 INST.VENT.GR.SANIT.VAR.1 | I5: [ ron ]
B6: Nr. | C6: Capitol lucrari | D6: U/M | G6: Cantitatea | H6: Pretul unitar | I6: Valoare
B7: Crt. | C7: Simbol | H7: a)materiale
C8: Denumire resursa | H8: b)manopera
C9: Observatii | H9: c)utilaj
C10: Corectii | H10: d)transport
C11: Liste Anexe | H11: Total(a+b+c+d)
B12: 1 | C12: SB08E 99 | D12: M | G12: 29 | H12: 63 | I12: =G12*H12 -> 1827 | J12: 1
A13: TEAVA DIN MAT.PLASTIC(PE,PP,PP-R)PT.CANAL, APARENT- INGROPATA SUB PARDOSEALA, IMB. GARNITURA,D=110MM, TEVI DIN P.V.C.RIGID TIP M 110X 5,3 | H13: 42 | I13: =G12*H13 -> 1218 | J13: 2
H14: =H12+H13 -> 105 | I14: =I12+I13 -> 3045 | J14: 5
B15: 2 | C15: SB08F 99 | D15: M | G15: 29 | H15: 67 | I15: =G15*H15 -> 1943 | J15: 1
A16: TEAVA DIN MAT.PLASTIC(PE,PP,PP-R)PT.CANAL, APARENT- INGROPATA SUB PARDOSEALA, IMB. GARNITURA,D=125MM, TEVI DIN P.V.C.RIGID TIP M 125X 6 | H16: 55 | I16: =G15*H16 -> 1595 | J16: 2
H17: =H15+H16 -> 122 | I17: =I15+I16 -> 3538 | J17: 5
B18: 3 | C18: SB08G 99 | D18: M | G18: 18 | H18: 70 | I18: =G18*H18 -> 1260 | J18: 1
A19: TEAVA DIN MAT.PLASTIC(PE,PP,PP-R)PT.CANAL, APARENT- INGROPATA SUB PARDOSEALA, IMB. GARNITURA,D=160MM, TEVI DIN P.V.C.RIGID TIP M 150X 7,5 | H19: 46 | I19: =G18*H19 -> 828 | J19: 2
H20: =H18+H19 -> 116 | I20: =I18+I19 -> 2088 | J20: 5
B21: 4 | C21: SB08G 99 | D21: M | G21: 12 | H21: 76 | I21: =G21*H21 -> 912 | J21: 1
A22: TEAVA DIN MAT.PLASTIC(PE,PP,PP-R)PT.CANAL, APARENT- INGROPATA SUB PARDOSEALA, IMB. GARNITURA,D=200MM, TEVI DIN P.V.C.RIGID TIP M 210X10 | H22: 63 | I22: =G21*H22 -> 756 | J22: 2
H23: =H21+H22 -> 139 | I23: =I21+I22 -> 1668 | J23: 5
B24: 5 | C24: IC40F 99 | D24: BUCATA | G24: 28 | H24: 23 | I24: =G24*H24 -> 644 | J24: 1
A25: BRATARA PT.FIXARE COND.OL PT.INST.INC.CENTR.SAU GAZE D=11/4-2" MONT.PRIN DIBLURI EXP PE ZID BETON, BRIDA FIXARE D.110 CU DIBLU OL/ZN GARNIT. ANTIZGOMOT | H25: 15 | I25: =G24*H25 -> 420 | J25: 2
H26: =H24+H25 -> 38 | I26: =I24+I25 -> 1064 | J26: 5
B27: 6 | C27: IC40F 99 | D27: BUCATA | G27: 26 | H27: 28 | I27: =G27*H27 -> 728 | J27: 1
A28: BRATARA PT.FIXARE COND.OL PT.INST.INC.CENTR.SAU GAZE D=11/4-2" MONT.PRIN DIBLURI EXP PE ZID BETON, BRIDA FIXARE D.125 CU DIBLU OL/ZN GARNIT. ANTIZGOMOT | H28: 23 | I28: =G27*H28 -> 598 | J28: 2
H29: =H27+H28 -> 51 | I29: =I27+I28 -> 1326 | J29: 5
B30: 7 | C30: IC40F 99 | D30: BUCATA | G30: 10 | H30: 32 | I30: =G30*H30 -> 320 | J30: 1
A31: BRATARA PT.FIXARE COND.OL PT.INST.INC.CENTR.SAU GAZE D=11/4-2" MONT.PRIN DIBLURI EXP PE ZID BETON, BRIDA FIXARE D.160 CU DIBLU OL/ZN GARNIT. ANTIZGOMOT | H31: 21 | I31: =G30*H31 -> 210 | J31: 2
H32: =H30+H31 -> 53 | I32: =I30+I31 -> 530 | J32: 5
B33: 8 | C33: IC40F 99 | D33: BUCATA | G33: 4 | H33: 34 | I33: =G33*H33 -> 136 | J33: 1
A34: BRATARA PT.FIXARE COND.OL PT.INST.INC.CENTR.SAU GAZE D=11/4-2" MONT.PRIN DIBLURI EXP PE ZID BETON, BRIDA FIXARE D.200 CU DIBLU OL/ZN GARNIT. ANTIZGOMOT | H34: 28 | I34: =G33*H34 -> 112 | J34: 2
H35: =H33+H34 -> 62 | I35: =I33+I34 -> 248 | J35: 5
B36: 9 | C36: SB09E 99 | D36: BUCATA | G36: 32 | H36: 46 | I36: =G36*H36 -> 1472 | J36: 1
A37: PIESE DE LEGATURA, MAT. PLASTIC (PE,PP,PP-R) PT.CANALIZARE, IMBINARE CU GARNITURA, D= 110MM, Coturi Dn100 * 90° , COT PVC TIP U LA 87 GR.30M DN 110 | H37: 30 | I37: =G36*H37 -> 960 | J37: 2
H38: =H36+H37 -> 76 | I38: =I36+I37 -> 2432 | J38: 5
B39: 10 | C39: SB09F 99 | D39: BUCATA | G39: 18 | H39: 48 | I39: =G39*H39 -> 864 | J39: 1
A40: PIESE DE LEGATURA, MAT. PLASTIC (PE,PP,PP-R) PT.CANALIZARE, IMBINARE CU GARNITURA, D= 125MM, Coturi Dn125 * 90° , COT PVC TIP U LA 87 GR.30M DN 125 | H40: 40 | I40: =G39*H40 -> 720 | J40: 2
...

Sheet O.06 D.01
A1: Formular F3 | J1: 1
A2: Obiectiv: UTCB REAB.,CONS.CFDP CORP C22-C.NOU
A3: LISTA_x000D_ cu cantitatile de lucrari pe categorii de lucrari
A4: Obiect: 06 INST.ELECTRICE
A5: Categorie: 01 INST.ELECTRICE | I5: [ ron ]
B6: Nr. | C6: Capitol lucrari | D6: U/M | G6: Cantitatea | H6: Pretul unitar | I6: Valoare
B7: Crt. | C7: Simbol | H7: a)materiale
C8: Denumire resursa | H8: b)manopera
C9: Observatii | H9: c)utilaj
C10: Corectii | H10: d)transport
C11: Liste Anexe | H11: Total(a+b+c+d)
B12: 1 | C12: EA15D 99 | D12: M | G12: 244 | H12: 0 | I12: =G12*H12 -> 0 | J12: 1
A13: SISTEM DE CANALETI-PLINTE, MONT.APARENT PE DIBLURI DIN PVC,LATIMEA > 30 MM, DIN METAL, Canal metalic 300 * 100 mm sustinere cabluri | H13: 0 | I13: =G12*H13 -> 0 | J13: 2
H14: =H12+H13 -> 0 | I14: =I12+I13 -> 0 | J14: 5
B15: 2 | C15: EA15D 99 | D15: M | G15: 102 | H15: 0 | I15: =G15*H15 -> 0 | J15: 1
A16: SISTEM DE CANALETI-PLINTE, MONT.APARENT PE DIBLURI DIN PVC,LATIMEA > 30 MM, DIN METAL, Canal metalic 200 * 60 mm sustinere cabluri | H16: 0 | I16: =G15*H16 -> 0 | J16: 2
H17: =H15+H16 -> 0 | I17: =I15+I16 -> 0 | J17: 5
B18: 3 | C18: EA01A 99 | D18: M | G18: 7601 | H18: 0 | I18: =G18*H18 -> 0 | J18: 1
A19: TUB DE PROTECTIE DIN MATERIAL PLASTIC, D.EXT. <= 25 MM, MONTAT INGROPAT, TUB IZOLAT TIP I.P. (BERGMAN) 13 | H19: 0 | I19: =G18*H19 -> 0 | J19: 2
H20: =H18+H19 -> 0 | I20: =I18+I19 -> 0 | J20: 5
B21: 4 | C21: EA01A 99 | D21: M | G21: 2040 | H21: 0 | I21: =G21*H21 -> 0 | J21: 1
A22: TUB DE PROTECTIE DIN MATERIAL PLASTIC, D.EXT. <= 25 MM, MONTAT INGROPAT, TUB IZOLAT TIP I.P. (BERGMAN) 16 | H22: 0 | I22: =G21*H22 -> 0 | J22: 2
H23: =H21+H22 -> 0 | I23: =I21+I22 -> 0 | J23: 5
B24: 5 | C24: EA01A 99 | D24: M | G24: 2720 | H24: 0 | I24: =G24*H24 -> 0 | J24: 1
A25: TUB DE PROTECTIE DIN MATERIAL PLASTIC, D.EXT. <= 25 MM, MONTAT INGROPAT, TUB IZOLAT TIP I.P.E.(PANTZER) 20 | H25: 0 | I25: =G24*H25 -> 0 | J25: 2
H26: =H24+H25 -> 0 | I26: =I24+I25 -> 0 | J26: 5
B27: 6 | C27: EA01A 99 | D27: M | G27: 120 | H27: 0 | I27: =G27*H27 -> 0 | J27: 1
A28: TUB DE PROTECTIE DIN MATERIAL PLASTIC, D.EXT. <= 25 MM, MONTAT INGROPAT, TUB IZOLAT TIP I.P. (BERGMAN) 25 | H28: 0 | I28: =G27*H28 -> 0 | J28: 2
H29: =H27+H28 -> 0 | I29: =I27+I28 -> 0 | J29: 5
B30: 7 | C30: EA01B 99 | D30: M | G30: 120 | H30: 0 | I30: =G30*H30 -> 0 | J30: 1
A31: TUB DE PROTECTIE DIN MATERIAL PLASTIC, D.EXT. > 25 MM, MONTAT INGROPAT, TUB IZOLAT TIP I.P. (BERGMAN) 32 | H31: 0 | I31: =G30*H31 -> 0 | J31: 2
H32: =H30+H31 -> 0 | I32: =I30+I31 -> 0 | J32: 5
B33: 8 | C33: EC01A 99 | D33: M | G33: 2584 | H33: 0 | I33: =G33*H33 -> 0 | J33: 1
A34: CABLU PT.INST.EL.LA LOC.DE LAMPA-PRIZA, S.COND.<4MMP, MONT.SCOABE PE:DIBLURI MAT.PLASTIC, Cablu Cyy 3*1.5, iluminat general | H34: 0 | I34: =G33*H34 -> 0 | J34: 2
H35: =H33+H34 -> 0 | I35: =I33+I34 -> 0 | J35: 5
B36: 9 | C36: EC01A 99 | D36: M | G36: 510 | H36: 0 | I36: =G36*H36 -> 0 | J36: 1
A37: CABLU PT.INST.EL.LA LOC.DE LAMPA-PRIZA,S.COND.<4MMP,MONT.SCOABE PE:DIBLURI MAT.PLASTIC , NHXH 3x1.5 mmp | H37: 0 | I37: =G36*H37 -> 0 | J37: 2
H38: =H36+H37 -> 0 | I38: =I36+I37 -> 0 | J38: 5
B39: 10 | C39: EC01A 99 | D39: M | G39: 3876 | H39: 0 | I39: =G39*H39 -> 0 | J39: 1
A40: CABLU PT.INST.EL.LA LOC.DE LAMPA-PRIZA,S.COND.<4MMP,MONT.SCOABE PE:DIBLURI MAT.PLASTIC, Cablu Cyy 3*2.5, prize si racorduri 230V | H40: 0 | I40: =G39*H40 -> 0 | J40: 2
...
