Workbook

Sheet Centraliz.General
A1: Formular F1
A2: Obiectiv: 01F Construire ansamblu educational compus din scoala, gradinita, cai de circulatie, spatii verzi, terenuri de sport, zone de joaca, corpuri de iluminat, spatiu de parcare, gard incinta,care se va amplasa în partea de nord a Bucurestiului
A4: CENTRALIZATORUL GENERAL
A7: Nr. | B7: Denumire | C7: Valoarea
A8: crt. | B8: Obiect | C8: exclusiv TVA
C9: ron
A10: 0 | B10: 1 | C10: 2
A11: 1 | B11: =Centralizator!B4 -> 00 CAPITOLUL 2 | C11: =Centralizator!G11 -> 12674.71
A12: 2 | B12: =Centralizator!B17 -> 000 CAP 1.3 + CAP 6.2 | C12: =Centralizator!G24 -> 1628.41
A13: 3 | B13: =Centralizator!B30 -> 01 SCOALA | C13: =Centralizator!G49 -> 2985555.1
A14: 4 | B14: =Centralizator!B54 -> 02 GRADINITA | C14: =Centralizator!G73 -> 1553574.6
A15: 5 | B15: =Centralizator!B78 -> 03 SPATII COMUNE (POMPE REZ. APA) | C15: =Centralizator!G90 -> 296021.86
A16: 6 | B16: =Centralizator!B95 -> 04 AMENAJARI EXTERIOARE | C16: =Centralizator!G108 -> 190336.62
A17: 7 | B17: =Centralizator!B113 -> 05 DTOE | C17: =Centralizator!G128 -> 22557.864
B18: TOTAL valoare (exclusiv TVA) | C18: =SUM(C11:C17) -> 5062349.2
B19: Taxa pe valoarea adaugata | C19: =C18*0.19 -> 961846.34
B20: Total valoare (inclusiv TVA) | C20: =C19+C18 -> 6024195.5

Sheet Centralizator
B1: Formular F2
B2: Obiectiv: 01F Construire ansamblu educational compus din scoala, gradinita, cai de circulatie, spatii verzi, terenuri de sport, zone de joaca, corpuri de iluminat, spatiu de parcare, gard incinta,care se va amplasa în partea de nord a Bucurestiului
B3: CENTRALIZATORUL_x000D_ cheltuielilor pe categorii de lucrari, pt.obiectul
B4: 00 CAPITOLUL 2
A5: Nr. | B5: Nr. cap./subcap | G5: Valoarea
A6: crt. | B6: deviz | C6: Cheltuieli pe categoria de lucrari | G6: exclusiv TVA
B7: general | G7: ron
A8: 0 | B8: 1 | G8: 2
A9: 1 | B9: 4.1. | C9: Constructii si instalatii aferente acestora
A10: 1 | B10: 4.1.1 | C10: 2 CHELTUIELEI PT.ASIG.UTILITATI | G10: ='O.00 D.2'!I88 -> 12674.71
C11: TOTAL I | G11: =G10 -> 12674.71
D12: TOTAL valoare (exclusiv TVA) | G12: =G11 -> 12674.71
D13: Taxa pe valoarea adaugata | G13: =G12*0.19 -> 2408.1949
D14: Total valoare (inclusiv TVA) | G14: =G13+G12 -> 15082.905
B16: CENTRALIZATORUL_x000D_ cheltuielilor pe categorii de lucrari, pt.obiectul
B17: 000 CAP 1.3 + CAP 6.2
A18: Nr. | B18: Nr. cap./subcap | G18: Valoarea
A19: crt. | B19: deviz | C19: Cheltuieli pe categoria de lucrari | G19: exclusiv TVA
B20: general | G20: ron
A21: 0 | B21: 1 | G21: 2
A22: 1 | B22: 4.1. | C22: Constructii si instalatii aferente acestora
A23: 3 | B23: 4.1.3 | C23: 6.2 PROBE TEHNOLOGICE SI TESTE | G23: ='O.000 D.6.2'!I38 -> 1628.41
C24: TOTAL I | G24: =G23 -> 1628.41
D25: TOTAL valoare (exclusiv TVA) | G25: =G24 -> 1628.41
D26: Taxa pe valoarea adaugata | G26: =G25*0.19 -> 309.3979
D27: Total valoare (inclusiv TVA) | G27: =G25+G26 -> 1937.8079
B29: CENTRALIZATORUL_x000D_ cheltuielilor pe categorii de lucrari, pt.obiectul
B30: 01 SCOALA
A31: Nr. | B31: Nr. cap./subcap | G31: Valoarea
A32: crt. | B32: deviz | C32: Cheltuieli pe categoria de lucrari | G32: exclusiv TVA
B33: general | G33: ron
A34: 0 | B34: 1 | G34: 2
A35: 1 | B35: 4.1. | C35: Constructii si instalatii aferente acestora
A36: 4 | B36: 4.1.4 | C36: 04 INSTALATII SANITARE | G36: ='O.01 D.04'!I604 -> 295874.1
A37: 5 | B37: 4.1.5 | C37: 05 INST. INCAL-CENTRALA TERMICA | G37: ='O.01 D.05'!I467 -> 126243.75
A38: 6 | B38: 4.1.6 | C38: 06 MONTAJ ECHIPAMENTE CT | G38: ='O.01 D.06'!I131 -> 7184.658
A39: 7 | B39: 4.1.7 | C39: 07 INCALZIRE CU CORPURI STATICE (CALORIFERE SI CONVECTOARE DE PARDOSEALA) | G39: ='O.01 D.07'!I383 -> 163947.27
A40: 8 | B40: 4.1.8 | C40: 08 INCALZIRE IN PARDOSEALA | G40: ='O.01 D.08'!I281 -> 239662.92
A41: 9 | B41: 4.1.9 | C41: 09 INSTALATII DE CLIMATIZARE CU VENTILOCONVECTOARE | G41: ='O.01 D.09'!I272 -> 168636.73
A42: 10 | B42: 4.1.10 | C42: 10 INSTALATII DE VENTILARE | G42: ='O.01 D.10'!I348 -> 655307.89
...

Sheet F4
A1: Formular F4
A2: Obiectiv: 01F Construire ansamblu educational compus din scoala, gradinita, cai de circulatie, spatii verzi, terenuri de sport, zone de joaca, corpuri de iluminat, spatiu de parcare, gard incinta,care se va amplasa în partea de nord a Bucurestiului
A3: LISTA_x000D_ cu cantitatile de utilaje si echipamente tehnologice, inclusiv dotari
H4: [ ron ]
A5: Nr. | B5: Cod | C5: Denumirea | D5: U/M | E5: Cantitatea | F5: Pretul unitar | G5: Valoarea | H5: Fisa tehnica
A6: Crt. | F6: (exclusiv TVA) | H6: atasata
A7: 20 | B7: Obiect 01 SCOALA
B8: a) Utilaje, echipamente tehnologice si functionale care necesita montaj
B9: RE00087 | C9: AGREG AR 7/12 °C QR=430 KW,KIT HIDRAULIC,PE<210 KW, I<261A | D9: BUCATA | E9: 1 | F9: 156171.72 | G9: =F9*E9 -> 156171.72 | H9: F.T. 1.6.6
B10: RE00009 | C10: ARZATOR GAZ AUTOMAT, PROGRESIV MODULANT, PE GAZ QI=250 KW | D10: BUCATA | E10: 2 | F10: 4818.7981 | G10: =F10*E10 -> 9637.5961 | H10: F.T. 1.6.3B
B11: RE00086 | C11: BOILER 1 SERP+1 REZ 2KW,V=1000L, ACM 1775 L/H (LA 60°C) | D11: BUCATA | E11: 1 | F11: 4049.8661 | G11: =F11*E11 -> 4049.8661 | H11: F.T. 1.6.5
B12: RE00090 | C12: BUTELIE EGALIZARE PRESIUNE D323X9 (DN300).H=1.6M,RAC DN100 | D12: BUCATA | E12: 1 | F12: 2909.1442 | G12: =F12*E12 -> 2909.1442 | H12: F.T. 1.6.9
B13: RE00084 | C13: CAZAN OTEL IN CONDENSATIE,COMBUSTIBIL GAZOS,QI=250 KW | D13: BUCATA | E13: 2 | F13: 128323.15 | G13: =F13*E13 -> 256646.29 | H13: F.T. 1.6.3A
B14: RE00002 | C14: CEAS DE FATADA | D14: BUCATA | E14: 1 | F14: 15845.084 | G14: =F14*E14 -> 15845.084
B15: RE00081 | C15: CENTRALA DE TRATARE AER CU MONTAJ IN EXTERIOR L=14000 M³/H | D15: BUCATA | E15: 2 | F15: 91734.113 | G15: =F15*E15 -> 183468.23 | H15: F.T. 1.11.2
B16: RE00068 | C16: CENTRALA DE TRATARE DE AER CU MONTAJ DE TAVAN L=5500 M³/H | D16: BUCATA | E16: 1 | F16: 39024.104 | G16: =F16*E16 -> 39024.104 | H16: F.T. 1.11.1
B17: RE00127 | C17: CENTRALA TRATARE DE AER CU MONTAJ IN EXTERIOR L=20000 M³/H | D17: BUCATA | E17: 1 | F17: 128660.41 | G17: =F17*E17 -> 128660.41 | H17: F.T. 1.11.3
B18: RE00120 | C18: CLAPETA ANTIFOC CIRCULARA Ø100 MM RF120 MIN,SERVOMOTOR 24V | D18: BUCATA | E18: 6 | F18: 675.47755 | G18: =F18*E18 -> 4052.8653 | H18: F.T. 1.11.11
B19: RE00121 | C19: CLAPETA ANTIFOC CIRCULARA Ø125 MM RF120 MIN,SERVOMOTOR 24V | D19: BUCATA | E19: 20 | F19: 631.54575 | G19: =F19*E19 -> 12630.915 | H19: F.T. 1.11.12
B20: RE00122 | C20: CLAPETA ANTIFOC CIRCULARA Ø250 MM RF120 MIN,SERVOMOTOR 24V | D20: BUCATA | E20: 6 | F20: 737.04895 | G20: =F20*E20 -> 4422.2937 | H20: F.T. 1.11.13
B21: RE00123 | C21: CLAPETA ANTIFOC CIRCULARA Ø315 MM RF120 MIN,SERVOMOTOR 24V | D21: BUCATA | E21: 36 | F21: 799.22645 | G21: =F21*E21 -> 28772.152 | H21: F.T. 1.11.14
B22: RE00125 | C22: CLAPETA ANTIFOC RECTANG 1000X500MM,RF120 MIN,SERVOMOTOR 24V | D22: BUCATA | E22: 4 | F22: 1318.2362 | G22: =F22*E22 -> 5272.9446 | H22: F.T. 1.11.16
B23: RE00126 | C23: CLAPETA ANTIFOC RECTANG 1600X800MM,RF120 MIN,SERVOMOTOR 24V | D23: BUCATA | E23: 2 | F23: 2535.1595 | G23: =F23*E23 -> 5070.3191 | H23: F.T. 1.11.17
B24: RE00124 | C24: CLAPETA ANTIFOC RECTANG 400X250MM,RF120 MIN,SERVOMOTOR 24V | D24: BUCATA | E24: 2 | F24: 845.64535 | G24: =F24*E24 -> 1691.2907 | H24: F.T. 1.11.15
B25: RE00085 | C25: COS DE FUM Ø300 MM, H=5 M+CANAL RACORDARE Ø200 MM,L=1 M | D25: BUCATA | E25: 2 | F25: 2644.5711 | G25: =F25*E25 -> 5289.1421 | H25: F.T. 1.6.4.
B26: RE00001 | C26: LIFT PERSOANE - 3 STATII | D26: BUCATA | E26: 1 | F26: 54359.437 | G26: =F26*E26 -> 54359.437
B27: RE00093 | C27: POMPA CIRC ACM,H=2,0 MCA,G=4.5 M³/H,PE=150 W,800-3400 RPM | D27: BUCATA | E27: 1 | F27: 225.16615 | G27: =F27*E27 -> 225.16615 | H27: F.T. 1.6.12
B28: RE00119 | C28: POMPA CIRC AR VAS ACUM-DISTR,H=4, 0 MCA,G=75,0M³/H,PE=1000 W | D28: BUCATA | E28: 1 | F28: 11602.499 | G28: =F28*E28 -> 11602.499 | H28: F.T. 1.6.21
B29: RE00096 | C29: POMPA CIRC BAT INC CTA 14000M³/H,H=5MCA,G=2M³/H,PE=200W | D29: BUCATA | E29: 2 | F29: 1095.8392 | G29: =F29*E29 -> 2191.6785 | H29: F.T. 1.6.15
B30: RE00097 | C30: POMPA CIRC BAT INC CTA 5500M³/H,H=5MCA,G=1M³/H,PE=200W | D30: BUCATA | E30: 1 | F30: 1095.8392 | G30: =F30*E30 -> 1095.8392 | H30: F.T. 1.6.16
B31: RE00098 | C31: POMPA CIRC BAT RACIRE CTA 14000M³/H,H=4MCA,G=7M³/H,PE=500W | D31: BUCATA | E31: 2 | F31: 3244.0771 | G31: =F31*E31 -> 6488.1542 | H31: F.T. 1.6.17
B32: RE00099 | C32: POMPA CIRC BAT RACIRE CTA 5500M³/H,H=4MCA,G=5M³/H,PE=500W | D32: BUCATA | E32: 1 | F32: 3244.0771 | G32: =F32*E32 -> 3244.0771 | H32: F.T. 1.6.18
B33: RE00091 | C33: POMPA CIRC CAZAN,H=3,0 MCA,G=11 M³/H,PE=500 W,800-3400 RPM | D33: BUCATA | E33: 2 | F33: 2689.6732 | G33: =F33*E33 -> 5379.3465 | H33: F.T. 1.6.10
B34: RE00095 | C34: POMPA CIRC INC CALOR,H=6,0 MCA,G=2.5 M³/H,PE=100W,800-3400RP | D34: BUCATA | E34: 1 | F34: 1186.0855 | G34: =F34*E34 -> 1186.0855 | H34: F.T. 1.6.14
B35: RE00094 | C35: POMPA CIRC INC PARD,H=10,0 MCA,G=10 M³/H,PE=500W,800-3400RPM | D35: BUCATA | E35: 1 | F35: 4183.647 | G35: =F35*E35 -> 4183.647 | H35: F.T. 1.6.13
B36: RE00100 | C36: POMPA CIRC VENTILOCONVECTOARE,H=20MCA,G=43.5M³/H,PE=500W | D36: BUCATA | E36: 1 | F36: 16677.333 | G36: =F36*E36 -> 16677.333 | H36: F.T. 1.6.19
B37: RE00092 | C37: POMPA RECIRC CAZAN,H=3,0 MCA,G=2 M³/H,PE=500 W,800-3400 RPM | D37: BUCATA | E37: 2 | F37: 214.4967 | G37: =F37*E37 -> 428.9934 | H37: F.T. 1.6.11
B38: RE00003 | C38: SIGLA DECORATIVA 14 LITERE | D38: BUCATA | E38: 1 | F38: 23990.797 | G38: =F38*E38 -> 23990.797
B39: RE00082 | C39: SISTEM FOTOVOLTAIC 100-110 KW, INVERTOR TRIFAZAT ON GRID, C | D39: ANS | E39: 1 | F39: 156725.74 | G39: =F39*E39 -> 156725.74 | H39: F.T. 1.1
B40: RE00027 | C40: STATIE DE DEDURIZARE 1,2 M³/H | D40: BUCATA | E40: 1 | F40: 1631.5794 | G40: =F40*E40 -> 1631.5794 | H40: F.T. 1.6.2
...

Sheet O.00 D.2
A1: Formular F3 | J1: 1
A2: Obiectiv: 01F Construire ansamblu educational compus din scoala, gradinita, cai de circulatie, spatii verzi, terenuri de sport, zone de joaca, corpuri de iluminat, spatiu de parcare, gard incinta,care se va amplasa în partea de nord a Bucurestiului
A3: LISTA_x000D_ cu cantitatile de lucrari pe categorii de lucrari
A4: Obiect: 00 CAPITOLUL 2
A5: Categorie: 2 CHELTUIELEI PT.ASIG.UTILITATI | I5: [ ron ]
B6: Nr. | C6: Capitol lucrari | D6: U/M | G6: Cantitatea | H6: Pretul unitar | I6: Valoare
B7: Crt. | C7: Simbol | H7: a)materiale
C8: Denumire resursa | H8: b)manopera
C9: Observatii | H9: c)utilaj
C10: Corectii | H10: d)transport
C11: Liste Anexe | H11: Total(a+b+c+d)
B12: 1 | C12: ACE134A01+ | D12: M | G12: 30 | H12: 74.15 | I12: =G12*H12 -> 2224.5 | J12: 1
D13: =SUBSTITUTE("Sp.mat: 0.00%",".",IF(VALUE("1.2")=1.2,".",","),2) -> Sp.mat: 0.00% | F13: =SUBSTITUTE("Sp.man: 0.00%",".",IF(VALUE("1.2")=1.2,".",","),2) -> Sp.man: 0.00% | G13: =SUBSTITUTE("Sp.uti: 0.00%",".",IF(VALUE("1.2")=1.2,".",","),2) -> Sp.uti: 0.00% | H13: 4.03 | I13: =G12*H13 -> 120.9 | J13: 2
A14: TEAVA PVC CU MUFA SI GARNITURA PT. CANALIZARE EXTERIOARA GRAVITATIONALA D = 250 MM | H14: 0 | I14: =G12*H14 -> 0 | J14: 3 | K14: 0 | L14: 0 | M14: =I14-K14-L14 -> 0
H15: 0 | I15: =G12*H15 -> 0 | J15: 4 | N15: =IF(ISERR(SEARCH("TRA* 82",C12)),IF(Q15+R15+S15=0,0,I15*(Q15/(Q15+R15+S15))),I15) -> 0 | O15: =IF(ISERR(SEARCH("TRA* 82",C12)),IF(Q15+R15+S15=0,0,I15*(R15/(Q15+R15+S15))),0) -> 0 | P15: =IF(ISERR(SEARCH("TRA* 82",C12)),I15-N15-O15,0) -> 0 | Q15: 0 | R15: 0 | S15: 0
H16: =H12+H13+H14+H15 -> 78.18 | I16: =I12+I13+I14+I15 -> 2345.4 | J16: 5
B17: 2 | C17: ACD04B1 82 | D17: BUCATA | G17: 2 | H17: 618.25 | I17: =G17*H17 -> 1236.5 | J17: 1
D18: =SUBSTITUTE("Sp.mat: 0.00%",".",IF(VALUE("1.2")=1.2,".",","),2) -> Sp.mat: 0.00% | F18: =SUBSTITUTE("Sp.man: 0.00%",".",IF(VALUE("1.2")=1.2,".",","),2) -> Sp.man: 0.00% | G18: =SUBSTITUTE("Sp.uti: 0.00%",".",IF(VALUE("1.2")=1.2,".",","),2) -> Sp.uti: 0.00% | H18: 180.35 | I18: =G17*H18 -> 360.7 | J18: 2
A19: CAMIN CANALIZARE MENAJERA 800 CU RAMA SI CAPAC CAROSABIL | H19: 49.55 | I19: =G17*H19 -> 99.1 | J19: 3 | K19: 185.625 | L19: 0 | M19: =I19-K19-L19 -> -86.525
H20: =0 -> 0 | I20: =G17*H20 -> 0 | J20: 4 | N20: =IF(ISERR(SEARCH("TRA* 82",C17)),IF(Q20+R20+S20=0,0,I20*(Q20/(Q20+R20+S20))),I20) -> 0 | O20: =IF(ISERR(SEARCH("TRA* 82",C17)),IF(Q20+R20+S20=0,0,I20*(R20/(Q20+R20+S20))),0) -> 0 | P20: =IF(ISERR(SEARCH("TRA* 82",C17)),I20-N20-O20,0) -> 0 | Q20: 0 | R20: 0 | S20: 0
H21: =H17+H18+H19+H20 -> 848.15 | I21: =I17+I18+I19+I20 -> 1696.3 | J21: 5
B22: 3 | C22: ACD04B1 82 | D22: BUCATA | G22: 2 | H22: 618.25 | I22: =G22*H22 -> 1236.5 | J22: 1
D23: =SUBSTITUTE("Sp.mat: 0.00%",".",IF(VALUE("1.2")=1.2,".",","),2) -> Sp.mat: 0.00% | F23: =SUBSTITUTE("Sp.man: 0.00%",".",IF(VALUE("1.2")=1.2,".",","),2) -> Sp.man: 0.00% | G23: =SUBSTITUTE("Sp.uti: 0.00%",".",IF(VALUE("1.2")=1.2,".",","),2) -> Sp.uti: 0.00% | H23: 180.35 | I23: =G22*H23 -> 360.7 | J23: 2
A24: CAMIN CANALIZARE MENAJERA 800 CU RAMA SI CAPAC NECAROSABIL | H24: 49.55 | I24: =G22*H24 -> 99.1 | J24: 3 | K24: 185.625 | L24: 0 | M24: =I24-K24-L24 -> -86.525
H25: 0 | I25: =G22*H25 -> 0 | J25: 4 | N25: =IF(ISERR(SEARCH("TRA* 82",C22)),IF(Q25+R25+S25=0,0,I25*(Q25/(Q25+R25+S25))),I25) -> 0 | O25: =IF(ISERR(SEARCH("TRA* 82",C22)),IF(Q25+R25+S25=0,0,I25*(R25/(Q25+R25+S25))),0) -> 0 | P25: =IF(ISERR(SEARCH("TRA* 82",C22)),I25-N25-O25,0) -> 0 | Q25: 0 | R25: 0 | S25: 0
H26: =H22+H23+H24+H25 -> 848.15 | I26: =I22+I23+I24+I25 -> 1696.3 | J26: 5
B27: 4 | C27: SF05F1 | D27: M | G27: 30 | H27: 0.27 | I27: =G27*H27 -> 8.1 | J27: 1
D28: =SUBSTITUTE("Sp.mat: 0.00%",".",IF(VALUE("1.2")=1.2,".",","),2) -> Sp.mat: 0.00% | F28: =SUBSTITUTE("Sp.man: 0.00%",".",IF(VALUE("1.2")=1.2,".",","),2) -> Sp.man: 0.00% | G28: =SUBSTITUTE("Sp.uti: 0.00%",".",IF(VALUE("1.2")=1.2,".",","),2) -> Sp.uti: 0.00% | H28: 3.4 | I28: =G27*H28 -> 102 | J28: 2
A29: EFECTUAREA PROBEI DE ETANSEITATE LA PRESIUNE A CONDUCTELOR AVAND DIAMETRUL MAX DE 500MM | H29: 0.19 | I29: =G27*H29 -> 5.7 | J29: 3 | K29: 0 | L29: 10.95345 | M29: =I29-K29-L29 -> -5.25345
H30: =0 -> 0 | I30: =G27*H30 -> 0 | J30: 4 | N30: =IF(ISERR(SEARCH("TRA* 82",C27)),IF(Q30+R30+S30=0,0,I30*(Q30/(Q30+R30+S30))),I30) -> 0 | O30: =IF(ISERR(SEARCH("TRA* 82",C27)),IF(Q30+R30+S30=0,0,I30*(R30/(Q30+R30+S30))),0) -> 0 | P30: =IF(ISERR(SEARCH("TRA* 82",C27)),I30-N30-O30,0) -> 0 | Q30: 0 | R30: 0 | S30: 0
H31: =H27+H28+H29+H30 -> 3.86 | I31: =I27+I28+I29+I30 -> 115.8 | J31: 5
B32: 5 | C32: ACE08A1 82 | D32: M CUB | G32: 3 | H32: 41.15 | I32: =G32*H32 -> 123.45 | J32: 1
D33: =SUBSTITUTE("Sp.mat: 0.00%",".",IF(VALUE("1.2")=1.2,".",","),2) -> Sp.mat: 0.00% | F33: =SUBSTITUTE("Sp.man: 0.00%",".",IF(VALUE("1.2")=1.2,".",","),2) -> Sp.man: 0.00% | G33: =SUBSTITUTE("Sp.uti: 0.00%",".",IF(VALUE("1.2")=1.2,".",","),2) -> Sp.uti: 0.00% | H33: 9.77 | I33: =G32*H33 -> 29.31 | J33: 2
A34: UMPLUTURA IN SANT.LA COND.DE ALIM.CU APA SI CANALIZARE CU: NISIP $ | H34: =(1+IF(OR(ISERR(FIND(":",G33)),ISERR(FIND("%",G33))),0,MID(G33,FIND(":",G33)+2,FIND("%",G33)-FIND(":",G33)-2)/100))*0 -> 0 | I34: =G32*H34 -> 0 | J34: 3 | K34: 0 | L34: 0 | M34: =I34-K34-L34 -> 0
H35: =0 -> 0 | I35: =G32*H35 -> 0 | J35: 4 | N35: =IF(ISERR(SEARCH("TRA* 82",C32)),IF(Q35+R35+S35=0,0,I35*(Q35/(Q35+R35+S35))),I35) -> 0 | O35: =IF(ISERR(SEARCH("TRA* 82",C32)),IF(Q35+R35+S35=0,0,I35*(R35/(Q35+R35+S35))),0) -> 0 | P35: =IF(ISERR(SEARCH("TRA* 82",C32)),I35-N35-O35,0) -> 0 | Q35: 0 | R35: 0 | S35: 0
H36: =H32+H33+H34+H35 -> 50.92 | I36: =I32+I33+I34+I35 -> 152.76 | J36: 5
B37: 6 | C37: TSA01XC 91 | D37: M CUB | G37: 30 | H37: =(1+IF(OR(ISERR(FIND(":",D38)),ISERR(FIND("%",D38))),0,MID(D38,FIND(":",D38)+2,FIND("%",D38)-FIND(":",D38)-2)/100))*0 -> 0 | I37: =G37*H37 -> 0 | J37: 1
D38: =SUBSTITUTE("Sp.mat: 0.00%",".",IF(VALUE("1.2")=1.2,".",","),2) -> Sp.mat: 0.00% | F38: =SUBSTITUTE("Sp.man: 0.00%",".",IF(VALUE("1.2")=1.2,".",","),2) -> Sp.man: 0.00% | G38: =SUBSTITUTE("Sp.uti: 0.00%",".",IF(VALUE("1.2")=1.2,".",","),2) -> Sp.uti: 0.00% | H38: 33.64 | I38: =G37*H38 -> 1009.2 | J38: 2
A39: SAPATURA MANUALA DE PAM.IN SPATII INTINSE LA DEBLEE LA CANALE,GROPI,INDEPART.STRAT VEG.TEREN TARE | H39: =(1+IF(OR(ISERR(FIND(":",G38)),ISERR(FIND("%",G38))),0,MID(G38,FIND(":",G38)+2,FIND("%",G38)-FIND(":",G38)-2)/100))*0 -> 0 | I39: =G37*H39 -> 0 | J39: 3 | K39: 0 | L39: 0 | M39: =I39-K39-L39 -> 0
H40: =0 -> 0 | I40: =G37*H40 -> 0 | J40: 4 | N40: =IF(ISERR(SEARCH("TRA* 82",C37)),IF(Q40+R40+S40=0,0,I40*(Q40/(Q40+R40+S40))),I40) -> 0 | O40: =IF(ISERR(SEARCH("TRA* 82",C37)),IF(Q40+R40+S40=0,0,I40*(R40/(Q40+R40+S40))),0) -> 0 | P40: =IF(ISERR(SEARCH("TRA* 82",C37)),I40-N40-O40,0) -> 0 | Q40: 0 | R40: 0 | S40: 0
...

Sheet O.000 D.6.2
A1: Formular F3 | J1: 1
A2: Obiectiv: 01F Construire ansamblu educational compus din scoala, gradinita, cai de circulatie, spatii verzi, terenuri de sport, zone de joaca, corpuri de iluminat, spatiu de parcare, gard incinta,care se va amplasa în partea de nord a Bucurestiului
A3: LISTA_x000D_ cu cantitatile de lucrari pe categorii de lucrari
A4: Obiect: 000 CAP 1.3 + CAP 6.2
A5: Categorie: 6.2 PROBE TEHNOLOGICE SI TESTE | I5: [ ron ]
B6: Nr. | C6: Capitol lucrari | D6: U/M | G6: Cantitatea | H6: Pretul unitar | I6: Valoare
B7: Crt. | C7: Simbol | H7: a)materiale
C8: Denumire resursa | H8: b)manopera
C9: Observatii | H9: c)utilaj
C10: Corectii | H10: d)transport
C11: Liste Anexe | H11: Total(a+b+c+d)
B12: 1 | C12: YC01 82 | D12: LEI | G12: 500 | H12: =266.95/G12 -> 0.5339 | I12: =G12*H12 -> 266.95 | J12: 1
D13: =SUBSTITUTE("Sp.mat: 0.00%",".",IF(VALUE("1.2")=1.2,".",","),2) -> Sp.mat: 0.00% | F13: =SUBSTITUTE("Sp.man: 0.00%",".",IF(VALUE("1.2")=1.2,".",","),2) -> Sp.man: 0.00% | G13: =SUBSTITUTE("Sp.uti: 0.00%",".",IF(VALUE("1.2")=1.2,".",","),2) -> Sp.uti: 0.00% | H13: =(1+IF(OR(ISERR(FIND(":",F13)),ISERR(FIND("%",F13))),0,MID(F13,FIND(":",F13)+2,FIND("%",F13)-FIND(":",F13)-2)/100))*0 -> 0 | I13: =G12*H13 -> 0 | J13: 2
A14: PROBA TERASA - ETANSEITATE LA APA - GRADINITA | H14: =(1+IF(OR(ISERR(FIND(":",G13)),ISERR(FIND("%",G13))),0,MID(G13,FIND(":",G13)+2,FIND("%",G13)-FIND(":",G13)-2)/100))*0 -> 0 | I14: =G12*H14 -> 0 | J14: 3 | K14: 0 | L14: 0 | M14: =I14-K14-L14 -> 0
H15: =0 -> 0 | I15: =G12*H15 -> 0 | J15: 4 | N15: =IF(ISERR(SEARCH("TRA* 82",C12)),IF(Q15+R15+S15=0,0,I15*(Q15/(Q15+R15+S15))),I15) -> 0 | O15: =IF(ISERR(SEARCH("TRA* 82",C12)),IF(Q15+R15+S15=0,0,I15*(R15/(Q15+R15+S15))),0) -> 0 | P15: =IF(ISERR(SEARCH("TRA* 82",C12)),I15-N15-O15,0) -> 0 | Q15: 0 | R15: 0 | S15: 0
H16: =H12+H13+H14+H15 -> 0.5339 | I16: =I12+I13+I14+I15 -> 266.95 | J16: 5
B17: 2 | C17: YC01 82 | D17: LEI | G17: 750 | H17: =400.43/G17 -> 0.53390667 | I17: =G17*H17 -> 400.43 | J17: 1
D18: =SUBSTITUTE("Sp.mat: 0.00%",".",IF(VALUE("1.2")=1.2,".",","),2) -> Sp.mat: 0.00% | F18: =SUBSTITUTE("Sp.man: 0.00%",".",IF(VALUE("1.2")=1.2,".",","),2) -> Sp.man: 0.00% | G18: =SUBSTITUTE("Sp.uti: 0.00%",".",IF(VALUE("1.2")=1.2,".",","),2) -> Sp.uti: 0.00% | H18: =(1+IF(OR(ISERR(FIND(":",F18)),ISERR(FIND("%",F18))),0,MID(F18,FIND(":",F18)+2,FIND("%",F18)-FIND(":",F18)-2)/100))*0 -> 0 | I18: =G17*H18 -> 0 | J18: 2
A19: PROBA TERASA - ETANSEITATE LA APA - SCOALA | H19: =(1+IF(OR(ISERR(FIND(":",G18)),ISERR(FIND("%",G18))),0,MID(G18,FIND(":",G18)+2,FIND("%",G18)-FIND(":",G18)-2)/100))*0 -> 0 | I19: =G17*H19 -> 0 | J19: 3 | K19: 0 | L19: 0 | M19: =I19-K19-L19 -> 0
H20: =0 -> 0 | I20: =G17*H20 -> 0 | J20: 4 | N20: =IF(ISERR(SEARCH("TRA* 82",C17)),IF(Q20+R20+S20=0,0,I20*(Q20/(Q20+R20+S20))),I20) -> 0 | O20: =IF(ISERR(SEARCH("TRA* 82",C17)),IF(Q20+R20+S20=0,0,I20*(R20/(Q20+R20+S20))),0) -> 0 | P20: =IF(ISERR(SEARCH("TRA* 82",C17)),I20-N20-O20,0) -> 0 | Q20: 0 | R20: 0 | S20: 0
H21: =H17+H18+H19+H20 -> 0.53390667 | I21: =I17+I18+I19+I20 -> 400.43 | J21: 5
B22: 3 | C22: YC01 82 | D22: LEI | G22: 600 | H22: =320.34/G22 -> 0.5339 | I22: =G22*H22 -> 320.34 | J22: 1
D23: =SUBSTITUTE("Sp.mat: 0.00%",".",IF(VALUE("1.2")=1.2,".",","),2) -> Sp.mat: 0.00% | F23: =SUBSTITUTE("Sp.man: 0.00%",".",IF(VALUE("1.2")=1.2,".",","),2) -> Sp.man: 0.00% | G23: =SUBSTITUTE("Sp.uti: 0.00%",".",IF(VALUE("1.2")=1.2,".",","),2) -> Sp.uti: 0.00% | H23: =(1+IF(OR(ISERR(FIND(":",F23)),ISERR(FIND("%",F23))),0,MID(F23,FIND(":",F23)+2,FIND("%",F23)-FIND(":",F23)-2)/100))*0 -> 0 | I23: =G22*H23 -> 0 | J23: 2
A24: PROBA ETANSEITATE AER- GRADINITA | H24: =(1+IF(OR(ISERR(FIND(":",G23)),ISERR(FIND("%",G23))),0,MID(G23,FIND(":",G23)+2,FIND("%",G23)-FIND(":",G23)-2)/100))*0 -> 0 | I24: =G22*H24 -> 0 | J24: 3 | K24: 0 | L24: 0 | M24: =I24-K24-L24 -> 0
H25: =0 -> 0 | I25: =G22*H25 -> 0 | J25: 4 | N25: =IF(ISERR(SEARCH("TRA* 82",C22)),IF(Q25+R25+S25=0,0,I25*(Q25/(Q25+R25+S25))),I25) -> 0 | O25: =IF(ISERR(SEARCH("TRA* 82",C22)),IF(Q25+R25+S25=0,0,I25*(R25/(Q25+R25+S25))),0) -> 0 | P25: =IF(ISERR(SEARCH("TRA* 82",C22)),I25-N25-O25,0) -> 0 | Q25: 0 | R25: 0 | S25: 0
H26: =H22+H23+H24+H25 -> 0.5339 | I26: =I22+I23+I24+I25 -> 320.34 | J26: 5
B27: 4 | C27: YC01 82 | D27: LEI | G27: 850 | H27: =453.82/G27 -> 0.53390588 | I27: =G27*H27 -> 453.82 | J27: 1
D28: =SUBSTITUTE("Sp.mat: 0.00%",".",IF(VALUE("1.2")=1.2,".",","),2) -> Sp.mat: 0.00% | F28: =SUBSTITUTE("Sp.man: 0.00%",".",IF(VALUE("1.2")=1.2,".",","),2) -> Sp.man: 0.00% | G28: =SUBSTITUTE("Sp.uti: 0.00%",".",IF(VALUE("1.2")=1.2,".",","),2) -> Sp.uti: 0.00% | H28: =(1+IF(OR(ISERR(FIND(":",F28)),ISERR(FIND("%",F28))),0,MID(F28,FIND(":",F28)+2,FIND("%",F28)-FIND(":",F28)-2)/100))*0 -> 0 | I28: =G27*H28 -> 0 | J28: 2
A29: PROBA ETANSEITATE AER - SCOALA | H29: =(1+IF(OR(ISERR(FIND(":",G28)),ISERR(FIND("%",G28))),0,MID(G28,FIND(":",G28)+2,FIND("%",G28)-FIND(":",G28)-2)/100))*0 -> 0 | I29: =G27*H29 -> 0 | J29: 3 | K29: 0 | L29: 0 | M29: =I29-K29-L29 -> 0
H30: =0 -> 0 | I30: =G27*H30 -> 0 | J30: 4 | N30: =IF(ISERR(SEARCH("TRA* 82",C27)),IF(Q30+R30+S30=0,0,I30*(Q30/(Q30+R30+S30))),I30) -> 0 | O30: =IF(ISERR(SEARCH("TRA* 82",C27)),IF(Q30+R30+S30=0,0,I30*(R30/(Q30+R30+S30))),0) -> 0 | P30: =IF(ISERR(SEARCH("TRA* 82",C27)),I30-N30-O30,0) -> 0 | Q30: 0 | R30: 0 | S30: 0
H31: =H27+H28+H29+H30 -> 0.53390588 | I31: =I27+I28+I29+I30 -> 453.82 | J31: 5
B32: 5 | C32: YC01 82 | D32: LEI | G32: 350 | H32: =186.87/G32 -> 0.53391429 | I32: =G32*H32 -> 186.87 | J32: 1
D33: =SUBSTITUTE("Sp.mat: 0.00%",".",IF(VALUE("1.2")=1.2,".",","),2) -> Sp.mat: 0.00% | F33: =SUBSTITUTE("Sp.man: 0.00%",".",IF(VALUE("1.2")=1.2,".",","),2) -> Sp.man: 0.00% | G33: =SUBSTITUTE("Sp.uti: 0.00%",".",IF(VALUE("1.2")=1.2,".",","),2) -> Sp.uti: 0.00% | H33: =(1+IF(OR(ISERR(FIND(":",F33)),ISERR(FIND("%",F33))),0,MID(F33,FIND(":",F33)+2,FIND("%",F33)-FIND(":",F33)-2)/100))*0 -> 0 | I33: =G32*H33 -> 0 | J33: 2
A34: PROBA ETANSEITATE AER - SALA DE SPORT | H34: =(1+IF(OR(ISERR(FIND(":",G33)),ISERR(FIND("%",G33))),0,MID(G33,FIND(":",G33)+2,FIND("%",G33)-FIND(":",G33)-2)/100))*0 -> 0 | I34: =G32*H34 -> 0 | J34: 3 | K34: 0 | L34: 0 | M34: =I34-K34-L34 -> 0
H35: =0 -> 0 | I35: =G32*H35 -> 0 | J35: 4 | N35: =IF(ISERR(SEARCH("TRA* 82",C32)),IF(Q35+R35+S35=0,0,I35*(Q35/(Q35+R35+S35))),I35) -> 0 | O35: =IF(ISERR(SEARCH("TRA* 82",C32)),IF(Q35+R35+S35=0,0,I35*(R35/(Q35+R35+S35))),0) -> 0 | P35: =IF(ISERR(SEARCH("TRA* 82",C32)),I35-N35-O35,0) -> 0 | Q35: 0 | R35: 0 | S35: 0
H36: =H32+H33+H34+H35 -> 0.53391429 | I36: =I32+I33+I34+I35 -> 186.87 | J36: 5
E37: =SUMIF(J12:J36,"1",I12:I36) -> 1628.41 | F37: =SUMIF(J12:J36,"2",I12:I36) -> 0 | G37: =SUMIF(J12:J36,"3",I12:I36) -> 0 | H37: =SUMIF(J12:J36,"4",I12:I36) -> 0 | I37: =SUMIF(J12:J36,"5",I12:I36) -> 1628.41 | K37: =SUMIF(J12:J36,"3",K12:K36) -> 0 | L37: =SUMIF(J12:J36,"3",L12:L36) -> 0 | M37: =SUMIF(J12:J36,"3",M12:M36) -> 0 | N37: =SUMIF(J12:J36,"4",N12:N36) -> 0 | O37: =SUMIF(J12:J36,"4",O12:O36) -> 0 | P37: =SUMIF(J12:J36,"4",P12:P36) -> 0 | Q37: =SUMIF(J12:J36,"4",Q12:Q36) -> 0 | R37: =SUMIF(J12:J36,"4",R12:R36) -> 0 | S37: =SUMIF(J12:J36,"4",S12:S36) -> 0
B38: TOTAL GENERAL | I38: =I37 -> 1628.41

Sheet O.01 D.04
A1: Formular F3 | J1: 1
A2: Obiectiv: 01F Construire ansamblu educational compus din scoala, gradinita, cai de circulatie, spatii verzi, terenuri de sport, zone de joaca, corpuri de iluminat, spatiu de parcare, gard incinta,care se va amplasa în partea de nord a Bucurestiului
A3: LISTA_x000D_ cu cantitatile de lucrari pe categorii de lucrari
A4: Obiect: 01 SCOALA
A5: Categorie: 04 INSTALATII SANITARE | I5: [ ron ]
B6: Nr. | C6: Capitol lucrari | D6: U/M | G6: Cantitatea | H6: Pretul unitar | I6: Valoare
B7: Crt. | C7: Simbol | H7: a)materiale
C8: Denumire resursa | H8: b)manopera
C9: Observatii | H9: c)utilaj
C10: Corectii | H10: d)transport
C11: Liste Anexe | H11: Total(a+b+c+d)
B12: 1 | C12: SD17B 99 | D12: BUCATA | G12: 19 | H12: 1082.47 | I12: =G12*H12 -> 20566.93 | J12: 1
D13: =SUBSTITUTE("Sp.mat: 0.00%",".",IF(VALUE("1.2")=1.2,".",","),2) -> Sp.mat: 0.00% | F13: =SUBSTITUTE("Sp.man: 0.00%",".",IF(VALUE("1.2")=1.2,".",","),2) -> Sp.man: 0.00% | G13: =SUBSTITUTE("Sp.uti: 0.00%",".",IF(VALUE("1.2")=1.2,".",","),2) -> Sp.uti: 0.00% | H13: =1217.29/G12 -> 64.067895 | I13: =G12*H13 -> 1217.29 | J13: 2
A14: HIDRANT INTERIOR, PENTRU CLADIRI, CU DIAMETRUL DE 2", PE PERETE (CUTIE+RAMA) | H14: =(1+IF(OR(ISERR(FIND(":",G13)),ISERR(FIND("%",G13))),0,MID(G13,FIND(":",G13)+2,FIND("%",G13)-FIND(":",G13)-2)/100))*0 -> 0 | I14: =G12*H14 -> 0 | J14: 3 | K14: 0 | L14: 0 | M14: =I14-K14-L14 -> 0
H15: =0 -> 0 | I15: =G12*H15 -> 0 | J15: 4 | N15: =IF(ISERR(SEARCH("TRA* 82",C12)),IF(Q15+R15+S15=0,0,I15*(Q15/(Q15+R15+S15))),I15) -> 0 | O15: =IF(ISERR(SEARCH("TRA* 82",C12)),IF(Q15+R15+S15=0,0,I15*(R15/(Q15+R15+S15))),0) -> 0 | P15: =IF(ISERR(SEARCH("TRA* 82",C12)),I15-N15-O15,0) -> 0 | Q15: 0 | R15: 0 | S15: 0
H16: =H12+H13+H14+H15 -> 1146.5379 | I16: =I12+I13+I14+I15 -> 21784.22 | J16: 5
B17: 2 | C17: SA02XC 91 | D17: M | G17: 85 | H17: =2098.23/G17 -> 24.685059 | I17: =G17*H17 -> 2098.23 | J17: 1
D18: =SUBSTITUTE("Sp.mat: 0.00%",".",IF(VALUE("1.2")=1.2,".",","),2) -> Sp.mat: 0.00% | F18: =SUBSTITUTE("Sp.man: 0.00%",".",IF(VALUE("1.2")=1.2,".",","),2) -> Sp.man: 0.00% | G18: =SUBSTITUTE("Sp.uti: 0.00%",".",IF(VALUE("1.2")=1.2,".",","),2) -> Sp.uti: 0.00% | H18: =1837.95/G17 -> 21.622941 | I18: =G17*H18 -> 1837.95 | J18: 2
A19: TEAVA OL ZN SUDATA LONG,CU FILET SI MUFA,PT.INST.MONT.LA CONST.CIVILE AVIND DIAMETRUL DE 1 1/2"-2" | H19: =(1+IF(OR(ISERR(FIND(":",G18)),ISERR(FIND("%",G18))),0,MID(G18,FIND(":",G18)+2,FIND("%",G18)-FIND(":",G18)-2)/100))*0 -> 0 | I19: =G17*H19 -> 0 | J19: 3 | K19: 0 | L19: 0 | M19: =I19-K19-L19 -> 0
H20: =0 -> 0 | I20: =G17*H20 -> 0 | J20: 4 | N20: =IF(ISERR(SEARCH("TRA* 82",C17)),IF(Q20+R20+S20=0,0,I20*(Q20/(Q20+R20+S20))),I20) -> 0 | O20: =IF(ISERR(SEARCH("TRA* 82",C17)),IF(Q20+R20+S20=0,0,I20*(R20/(Q20+R20+S20))),0) -> 0 | P20: =IF(ISERR(SEARCH("TRA* 82",C17)),I20-N20-O20,0) -> 0 | Q20: 0 | R20: 0 | S20: 0
H21: =H17+H18+H19+H20 -> 46.308 | I21: =I17+I18+I19+I20 -> 3936.18 | J21: 5
B22: 3 | C22: SA02XD 91 | D22: M | G22: 49 | H22: =1182.98/G22 -> 24.142449 | I22: =G22*H22 -> 1182.98 | J22: 1
D23: =SUBSTITUTE("Sp.mat: 0.00%",".",IF(VALUE("1.2")=1.2,".",","),2) -> Sp.mat: 0.00% | F23: =SUBSTITUTE("Sp.man: 0.00%",".",IF(VALUE("1.2")=1.2,".",","),2) -> Sp.man: 0.00% | G23: =SUBSTITUTE("Sp.uti: 0.00%",".",IF(VALUE("1.2")=1.2,".",","),2) -> Sp.uti: 0.00% | H23: =1334.22/G22 -> 27.22898 | I23: =G22*H23 -> 1334.22 | J23: 2
A24: TEAVA OL ZN SUDATA LONG,CU FILET SI MUFA,PT.INST.MONT.LA CONST.CIVILE AVIND DIAMETRUL DE 2 1/2"-3" | H24: =(1+IF(OR(ISERR(FIND(":",G23)),ISERR(FIND("%",G23))),0,MID(G23,FIND(":",G23)+2,FIND("%",G23)-FIND(":",G23)-2)/100))*0 -> 0 | I24: =G22*H24 -> 0 | J24: 3 | K24: 0 | L24: 0 | M24: =I24-K24-L24 -> 0
H25: =0 -> 0 | I25: =G22*H25 -> 0 | J25: 4 | N25: =IF(ISERR(SEARCH("TRA* 82",C22)),IF(Q25+R25+S25=0,0,I25*(Q25/(Q25+R25+S25))),I25) -> 0 | O25: =IF(ISERR(SEARCH("TRA* 82",C22)),IF(Q25+R25+S25=0,0,I25*(R25/(Q25+R25+S25))),0) -> 0 | P25: =IF(ISERR(SEARCH("TRA* 82",C22)),I25-N25-O25,0) -> 0 | Q25: 0 | R25: 0 | S25: 0
H26: =H22+H23+H24+H25 -> 51.371429 | I26: =I22+I23+I24+I25 -> 2517.2 | J26: 5
B27: 4 | C27: SA02XD 91 | D27: M | G27: 75 | H27: =2842.52/G27 -> 37.900267 | I27: =G27*H27 -> 2842.52 | J27: 1
D28: =SUBSTITUTE("Sp.mat: 0.00%",".",IF(VALUE("1.2")=1.2,".",","),2) -> Sp.mat: 0.00% | F28: =SUBSTITUTE("Sp.man: 0.00%",".",IF(VALUE("1.2")=1.2,".",","),2) -> Sp.man: 0.00% | G28: =SUBSTITUTE("Sp.uti: 0.00%",".",IF(VALUE("1.2")=1.2,".",","),2) -> Sp.uti: 0.00% | H28: =2042.17/G27 -> 27.228933 | I28: =G27*H28 -> 2042.17 | J28: 2
A29: TEAVA OL ZN SUDATA LONG,CU FILET SI MUFA,PT.INST.MONT.LA CONST.CIVILE AVIND DIAMETRUL DE 2 1/2"-3" | H29: =(1+IF(OR(ISERR(FIND(":",G28)),ISERR(FIND("%",G28))),0,MID(G28,FIND(":",G28)+2,FIND("%",G28)-FIND(":",G28)-2)/100))*0 -> 0 | I29: =G27*H29 -> 0 | J29: 3 | K29: 0 | L29: 0 | M29: =I29-K29-L29 -> 0
H30: =0 -> 0 | I30: =G27*H30 -> 0 | J30: 4 | N30: =IF(ISERR(SEARCH("TRA* 82",C27)),IF(Q30+R30+S30=0,0,I30*(Q30/(Q30+R30+S30))),I30) -> 0 | O30: =IF(ISERR(SEARCH("TRA* 82",C27)),IF(Q30+R30+S30=0,0,I30*(R30/(Q30+R30+S30))),0) -> 0 | P30: =IF(ISERR(SEARCH("TRA* 82",C27)),I30-N30-O30,0) -> 0 | Q30: 0 | R30: 0 | S30: 0
H31: =H27+H28+H29+H30 -> 65.1292 | I31: =I27+I28+I29+I30 -> 4884.69 | J31: 5
B32: 5 | C32: SA02XE 91 | D32: M | G32: 13 | H32: =707.69/G32 -> 54.437692 | I32: =G32*H32 -> 707.69 | J32: 1
D33: =SUBSTITUTE("Sp.mat: 0.00%",".",IF(VALUE("1.2")=1.2,".",","),2) -> Sp.mat: 0.00% | F33: =SUBSTITUTE("Sp.man: 0.00%",".",IF(VALUE("1.2")=1.2,".",","),2) -> Sp.man: 0.00% | G33: =SUBSTITUTE("Sp.uti: 0.00%",".",IF(VALUE("1.2")=1.2,".",","),2) -> Sp.uti: 0.00% | H33: =437.26/G32 -> 33.635385 | I33: =G32*H33 -> 437.26 | J33: 2
A34: TEAVA OL ZN SUDATA LONG,CU FILET SI MUFA,PT.INST.MONT.LA CONST.CIVILE AVIND DIAMETRUL DE 4" | H34: =(1+IF(OR(ISERR(FIND(":",G33)),ISERR(FIND("%",G33))),0,MID(G33,FIND(":",G33)+2,FIND("%",G33)-FIND(":",G33)-2)/100))*0 -> 0 | I34: =G32*H34 -> 0 | J34: 3 | K34: 0 | L34: 0 | M34: =I34-K34-L34 -> 0
H35: =0 -> 0 | I35: =G32*H35 -> 0 | J35: 4 | N35: =IF(ISERR(SEARCH("TRA* 82",C32)),IF(Q35+R35+S35=0,0,I35*(Q35/(Q35+R35+S35))),I35) -> 0 | O35: =IF(ISERR(SEARCH("TRA* 82",C32)),IF(Q35+R35+S35=0,0,I35*(R35/(Q35+R35+S35))),0) -> 0 | P35: =IF(ISERR(SEARCH("TRA* 82",C32)),I35-N35-O35,0) -> 0 | Q35: 0 | R35: 0 | S35: 0
H36: =H32+H33+H34+H35 -> 88.073077 | I36: =I32+I33+I34+I35 -> 1144.95 | J36: 5
B37: 6 | C37: SF05A 99 | D37: M | G37: 85 | H37: =(1+IF(OR(ISERR(FIND(":",D38)),ISERR(FIND("%",D38))),0,MID(D38,FIND(":",D38)+2,FIND("%",D38)-FIND(":",D38)-2)/100))*0 -> 0 | I37: =G37*H37 -> 0 | J37: 1
D38: =SUBSTITUTE("Sp.mat: 0.00%",".",IF(VALUE("1.2")=1.2,".",","),2) -> Sp.mat: 0.00% | F38: =SUBSTITUTE("Sp.man: 0.00%",".",IF(VALUE("1.2")=1.2,".",","),2) -> Sp.man: 0.00% | G38: =SUBSTITUTE("Sp.uti: 0.00%",".",IF(VALUE("1.2")=1.2,".",","),2) -> Sp.uti: 0.00% | H38: =81.69/G37 -> 0.96105882 | I38: =G37*H38 -> 81.69 | J38: 2
A39: SPALAREA INSTALATIEI DE APA, EXECUTATA DIN TEAVA DE OTEL ZINCATA, D= 3/8" - 2" | H39: =(1+IF(OR(ISERR(FIND(":",G38)),ISERR(FIND("%",G38))),0,MID(G38,FIND(":",G38)+2,FIND("%",G38)-FIND(":",G38)-2)/100))*0 -> 0 | I39: =G37*H39 -> 0 | J39: 3 | K39: 0 | L39: 0 | M39: =I39-K39-L39 -> 0
H40: =0 -> 0 | I40: =G37*H40 -> 0 | J40: 4 | N40: =IF(ISERR(SEARCH("TRA* 82",C37)),IF(Q40+R40+S40=0,0,I40*(Q40/(Q40+R40+S40))),I40) -> 0 | O40: =IF(ISERR(SEARCH("TRA* 82",C37)),IF(Q40+R40+S40=0,0,I40*(R40/(Q40+R40+S40))),0) -> 0 | P40: =IF(ISERR(SEARCH("TRA* 82",C37)),I40-N40-O40,0) -> 0 | Q40: 0 | R40: 0 | S40: 0
...

Sheet O.01 D.05
A1: Formular F3 | J1: 1
A2: Obiectiv: 01F Construire ansamblu educational compus din scoala, gradinita, cai de circulatie, spatii verzi, terenuri de sport, zone de joaca, corpuri de iluminat, spatiu de parcare, gard incinta,care se va amplasa în partea de nord a Bucurestiului
A3: LISTA_x000D_ cu cantitatile de lucrari pe categorii de lucrari
A4: Obiect: 01 SCOALA
A5: Categorie: 05 INST. INCAL-CENTRALA TERMICA | I5: [ ron ]
B6: Nr. | C6: Capitol lucrari | D6: U/M | G6: Cantitatea | H6: Pretul unitar | I6: Valoare
B7: Crt. | C7: Simbol | H7: a)materiale
C8: Denumire resursa | H8: b)manopera
C9: Observatii | H9: c)utilaj
C10: Corectii | H10: d)transport
C11: Liste Anexe | H11: Total(a+b+c+d)
B12: 1 | C12: IC11XC 91 | D12: BUCATA | G12: 1 | H12: 3956.2 | I12: =G12*H12 -> 3956.2 | J12: 1
D13: =SUBSTITUTE("Sp.mat: 0.00%",".",IF(VALUE("1.2")=1.2,".",","),2) -> Sp.mat: 0.00% | F13: =SUBSTITUTE("Sp.man: 0.00%",".",IF(VALUE("1.2")=1.2,".",","),2) -> Sp.man: 0.00% | G13: =SUBSTITUTE("Sp.uti: 0.00%",".",IF(VALUE("1.2")=1.2,".",","),2) -> Sp.uti: 0.00% | H13: 187.4 | I13: =G12*H13 -> 187.4 | J13: 2
A14: DISTRIBUITOR-COLECTOR MONTAT PE SUSTINATOR GATA CONFECTIONAT,AVIND DIAMETRUL DE 152 - 250 MM | H14: =(1+IF(OR(ISERR(FIND(":",G13)),ISERR(FIND("%",G13))),0,MID(G13,FIND(":",G13)+2,FIND("%",G13)-FIND(":",G13)-2)/100))*0 -> 0 | I14: =G12*H14 -> 0 | J14: 3 | K14: 0 | L14: 0 | M14: =I14-K14-L14 -> 0
H15: =0 -> 0 | I15: =G12*H15 -> 0 | J15: 4 | N15: =IF(ISERR(SEARCH("TRA* 82",C12)),IF(Q15+R15+S15=0,0,I15*(Q15/(Q15+R15+S15))),I15) -> 0 | O15: =IF(ISERR(SEARCH("TRA* 82",C12)),IF(Q15+R15+S15=0,0,I15*(R15/(Q15+R15+S15))),0) -> 0 | P15: =IF(ISERR(SEARCH("TRA* 82",C12)),I15-N15-O15,0) -> 0 | Q15: 0 | R15: 0 | S15: 0
H16: =H12+H13+H14+H15 -> 4143.6 | I16: =I12+I13+I14+I15 -> 4143.6 | J16: 5
B17: 2 | C17: IC11XC 91 | D17: BUCATA | G17: 1 | H17: 668.54 | I17: =G17*H17 -> 668.54 | J17: 1
D18: =SUBSTITUTE("Sp.mat: 0.00%",".",IF(VALUE("1.2")=1.2,".",","),2) -> Sp.mat: 0.00% | F18: =SUBSTITUTE("Sp.man: 0.00%",".",IF(VALUE("1.2")=1.2,".",","),2) -> Sp.man: 0.00% | G18: =SUBSTITUTE("Sp.uti: 0.00%",".",IF(VALUE("1.2")=1.2,".",","),2) -> Sp.uti: 0.00% | H18: 144.15 | I18: =G17*H18 -> 144.15 | J18: 2
A19: DISTRIBUITOR-COLECTOR MONTAT PE SUSTINATOR GATA CONFECTIONAT,AVIND DIAMETRUL DE 152 - 250 MM | H19: =(1+IF(OR(ISERR(FIND(":",G18)),ISERR(FIND("%",G18))),0,MID(G18,FIND(":",G18)+2,FIND("%",G18)-FIND(":",G18)-2)/100))*0 -> 0 | I19: =G17*H19 -> 0 | J19: 3 | K19: 0 | L19: 0 | M19: =I19-K19-L19 -> 0
H20: =0 -> 0 | I20: =G17*H20 -> 0 | J20: 4 | N20: =IF(ISERR(SEARCH("TRA* 82",C17)),IF(Q20+R20+S20=0,0,I20*(Q20/(Q20+R20+S20))),I20) -> 0 | O20: =IF(ISERR(SEARCH("TRA* 82",C17)),IF(Q20+R20+S20=0,0,I20*(R20/(Q20+R20+S20))),0) -> 0 | P20: =IF(ISERR(SEARCH("TRA* 82",C17)),I20-N20-O20,0) -> 0 | Q20: 0 | R20: 0 | S20: 0
H21: =H17+H18+H19+H20 -> 812.69 | I21: =I17+I18+I19+I20 -> 812.69 | J21: 5
B22: 3 | C22: IC11XD 91 | D22: BUCATA | G22: 1 | H22: 4025.61 | I22: =G22*H22 -> 4025.61 | J22: 1
D23: =SUBSTITUTE("Sp.mat: 0.00%",".",IF(VALUE("1.2")=1.2,".",","),2) -> Sp.mat: 0.00% | F23: =SUBSTITUTE("Sp.man: 0.00%",".",IF(VALUE("1.2")=1.2,".",","),2) -> Sp.man: 0.00% | G23: =SUBSTITUTE("Sp.uti: 0.00%",".",IF(VALUE("1.2")=1.2,".",","),2) -> Sp.uti: 0.00% | H23: 153.76 | I23: =G22*H23 -> 153.76 | J23: 2
A24: DISTRIBUITOR-COLECTOR MONTAT PE SUSTINATOR GATA CONFECTIONAT,AVIND DIAMETRUL DE 252 - 390 MM | H24: =(1+IF(OR(ISERR(FIND(":",G23)),ISERR(FIND("%",G23))),0,MID(G23,FIND(":",G23)+2,FIND("%",G23)-FIND(":",G23)-2)/100))*0 -> 0 | I24: =G22*H24 -> 0 | J24: 3 | K24: 0 | L24: 0 | M24: =I24-K24-L24 -> 0
H25: =0 -> 0 | I25: =G22*H25 -> 0 | J25: 4 | N25: =IF(ISERR(SEARCH("TRA* 82",C22)),IF(Q25+R25+S25=0,0,I25*(Q25/(Q25+R25+S25))),I25) -> 0 | O25: =IF(ISERR(SEARCH("TRA* 82",C22)),IF(Q25+R25+S25=0,0,I25*(R25/(Q25+R25+S25))),0) -> 0 | P25: =IF(ISERR(SEARCH("TRA* 82",C22)),I25-N25-O25,0) -> 0 | Q25: 0 | R25: 0 | S25: 0
H26: =H22+H23+H24+H25 -> 4179.37 | I26: =I22+I23+I24+I25 -> 4179.37 | J26: 5
B27: 4 | C27: IC11XD 91 | D27: BUCATA | G27: 1 | H27: 4025.61 | I27: =G27*H27 -> 4025.61 | J27: 1
D28: =SUBSTITUTE("Sp.mat: 0.00%",".",IF(VALUE("1.2")=1.2,".",","),2) -> Sp.mat: 0.00% | F28: =SUBSTITUTE("Sp.man: 0.00%",".",IF(VALUE("1.2")=1.2,".",","),2) -> Sp.man: 0.00% | G28: =SUBSTITUTE("Sp.uti: 0.00%",".",IF(VALUE("1.2")=1.2,".",","),2) -> Sp.uti: 0.00% | H28: 153.76 | I28: =G27*H28 -> 153.76 | J28: 2
A29: DISTRIBUITOR-COLECTOR MONTAT PE SUSTINATOR GATA CONFECTIONAT,AVIND DIAMETRUL DE 252 - 390 MM | H29: =(1+IF(OR(ISERR(FIND(":",G28)),ISERR(FIND("%",G28))),0,MID(G28,FIND(":",G28)+2,FIND("%",G28)-FIND(":",G28)-2)/100))*0 -> 0 | I29: =G27*H29 -> 0 | J29: 3 | K29: 0 | L29: 0 | M29: =I29-K29-L29 -> 0
H30: =0 -> 0 | I30: =G27*H30 -> 0 | J30: 4 | N30: =IF(ISERR(SEARCH("TRA* 82",C27)),IF(Q30+R30+S30=0,0,I30*(Q30/(Q30+R30+S30))),I30) -> 0 | O30: =IF(ISERR(SEARCH("TRA* 82",C27)),IF(Q30+R30+S30=0,0,I30*(R30/(Q30+R30+S30))),0) -> 0 | P30: =IF(ISERR(SEARCH("TRA* 82",C27)),I30-N30-O30,0) -> 0 | Q30: 0 | R30: 0 | S30: 0
H31: =H27+H28+H29+H30 -> 4179.37 | I31: =I27+I28+I29+I30 -> 4179.37 | J31: 5
B32: 5 | C32: EF03A1 82 | D32: BUCATA | G32: 1 | H32: 5709.93 | I32: =G32*H32 -> 5709.93 | J32: 1
D33: =SUBSTITUTE("Sp.mat: 0.00%",".",IF(VALUE("1.2")=1.2,".",","),2) -> Sp.mat: 0.00% | F33: =SUBSTITUTE("Sp.man: 0.00%",".",IF(VALUE("1.2")=1.2,".",","),2) -> Sp.man: 0.00% | G33: =SUBSTITUTE("Sp.uti: 0.00%",".",IF(VALUE("1.2")=1.2,".",","),2) -> Sp.uti: 0.00% | H33: 140.31 | I33: =G32*H33 -> 140.31 | J33: 2
A34: TABLOU ELECTRIC PANOU,DULAP,CELULA SAU PUPITRU GATA ECHIPAT,CU GREUTATEA <150KG | H34: =(1+IF(OR(ISERR(FIND(":",G33)),ISERR(FIND("%",G33))),0,MID(G33,FIND(":",G33)+2,FIND("%",G33)-FIND(":",G33)-2)/100))*0 -> 0 | I34: =G32*H34 -> 0 | J34: 3 | K34: 0 | L34: 0 | M34: =I34-K34-L34 -> 0
H35: =0 -> 0 | I35: =G32*H35 -> 0 | J35: 4 | N35: =IF(ISERR(SEARCH("TRA* 82",C32)),IF(Q35+R35+S35=0,0,I35*(Q35/(Q35+R35+S35))),I35) -> 0 | O35: =IF(ISERR(SEARCH("TRA* 82",C32)),IF(Q35+R35+S35=0,0,I35*(R35/(Q35+R35+S35))),0) -> 0 | P35: =IF(ISERR(SEARCH("TRA* 82",C32)),I35-N35-O35,0) -> 0 | Q35: 0 | R35: 0 | S35: 0
H36: =H32+H33+H34+H35 -> 5850.24 | I36: =I32+I33+I34+I35 -> 5850.24 | J36: 5
B37: 6 | C37: ID03A 99 | D37: BUCATA | G37: 1 | H37: 310.62 | I37: =G37*H37 -> 310.62 | J37: 1
D38: =SUBSTITUTE("Sp.mat: 0.00%",".",IF(VALUE("1.2")=1.2,".",","),2) -> Sp.mat: 0.00% | F38: =SUBSTITUTE("Sp.man: 0.00%",".",IF(VALUE("1.2")=1.2,".",","),2) -> Sp.man: 0.00% | G38: =SUBSTITUTE("Sp.uti: 0.00%",".",IF(VALUE("1.2")=1.2,".",","),2) -> Sp.uti: 0.00% | H38: 20.02 | I38: =G37*H38 -> 20.02 | J38: 2
A39: ROBINET CU CEP, CU 3 CAI,CU FLANSE, DN=15-20 MM ,CU PRESGARNITURA PTR.INST.DE INCALZIRE CENTRALA | H39: =(1+IF(OR(ISERR(FIND(":",G38)),ISERR(FIND("%",G38))),0,MID(G38,FIND(":",G38)+2,FIND("%",G38)-FIND(":",G38)-2)/100))*0 -> 0 | I39: =G37*H39 -> 0 | J39: 3 | K39: 0 | L39: 0 | M39: =I39-K39-L39 -> 0
H40: =0 -> 0 | I40: =G37*H40 -> 0 | J40: 4 | N40: =IF(ISERR(SEARCH("TRA* 82",C37)),IF(Q40+R40+S40=0,0,I40*(Q40/(Q40+R40+S40))),I40) -> 0 | O40: =IF(ISERR(SEARCH("TRA* 82",C37)),IF(Q40+R40+S40=0,0,I40*(R40/(Q40+R40+S40))),0) -> 0 | P40: =IF(ISERR(SEARCH("TRA* 82",C37)),I40-N40-O40,0) -> 0 | Q40: 0 | R40: 0 | S40: 0
...

Sheet O.01 D.06
A1: Formular F3 | J1: 1
A2: Obiectiv: 01F Construire ansamblu educational compus din scoala, gradinita, cai de circulatie, spatii verzi, terenuri de sport, zone de joaca, corpuri de iluminat, spatiu de parcare, gard incinta,care se va amplasa în partea de nord a Bucurestiului
A3: LISTA_x000D_ cu cantitatile de lucrari pe categorii de lucrari
A4: Obiect: 01 SCOALA
A5: Categorie: 06 MONTAJ ECHIPAMENTE CT | I5: [ ron ]
B6: Nr. | C6: Capitol lucrari | D6: U/M | G6: Cantitatea | H6: Pretul unitar | I6: Valoare
B7: Crt. | C7: Simbol | H7: a)materiale
C8: Denumire resursa | H8: b)manopera
C9: Observatii | H9: c)utilaj
C10: Corectii | H10: d)transport
C11: Liste Anexe | H11: Total(a+b+c+d)
B12: 1 | C12: IA14D 99 | D12: BUCATA | G12: 2 | H12: 148.66 | I12: =G12*H12 -> 297.32 | J12: 1
D13: =SUBSTITUTE("Sp.mat: 0.00%",".",IF(VALUE("1.2")=1.2,".",","),2) -> Sp.mat: 0.00% | F13: =SUBSTITUTE("Sp.man: 0.00%",".",IF(VALUE("1.2")=1.2,".",","),2) -> Sp.man: 0.00% | G13: =SUBSTITUTE("Sp.uti: 0.00%",".",IF(VALUE("1.2")=1.2,".",","),2) -> Sp.uti: 0.00% | H13: 720.77 | I13: =G12*H13 -> 1441.54 | J13: 2
A14: CAZAN PREP.AGENT TERMIC PTR.INCALZ.DE OTEL,MONOBLOC,AVAND PUTERE CALORICA 211-290 KW | H14: 2.43 | I14: =G12*H14 -> 4.86 | J14: 3 | K14: 0 | L14: 0 | M14: =I14-K14-L14 -> 4.86
H15: =0 -> 0 | I15: =G12*H15 -> 0 | J15: 4 | N15: =IF(ISERR(SEARCH("TRA* 82",C12)),IF(Q15+R15+S15=0,0,I15*(Q15/(Q15+R15+S15))),I15) -> 0 | O15: =IF(ISERR(SEARCH("TRA* 82",C12)),IF(Q15+R15+S15=0,0,I15*(R15/(Q15+R15+S15))),0) -> 0 | P15: =IF(ISERR(SEARCH("TRA* 82",C12)),I15-N15-O15,0) -> 0 | Q15: 0 | R15: 0 | S15: 0
A16: ASIMILAT MONTAJ | H16: =H12+H13+H14+H15 -> 871.86 | I16: =I12+I13+I14+I15 -> 1743.72 | J16: 5
A17: Cazan din otel în condensatie ce functioneaza cu combustibil gazos, Qi=250 kW, Lxaxh 1900x860x1400
A18: mm, 995 kg
B19: 2 | C19: IA34A 99 | D19: BUCATA | G19: 2 | H19: 10.23 | I19: =G19*H19 -> 20.46 | J19: 1
D20: =SUBSTITUTE("Sp.mat: 0.00%",".",IF(VALUE("1.2")=1.2,".",","),2) -> Sp.mat: 0.00% | F20: =SUBSTITUTE("Sp.man: 0.00%",".",IF(VALUE("1.2")=1.2,".",","),2) -> Sp.man: 0.00% | G20: =SUBSTITUTE("Sp.uti: 0.00%",".",IF(VALUE("1.2")=1.2,".",","),2) -> Sp.uti: 0.00% | H20: 80.09 | I20: =G19*H20 -> 160.18 | J20: 2
A21: ARZATOR CU ARDERE FORTATA PTR.COMBUSTIBIL GAZOS AVAND PUTEREA MAXIMA A FLACARII DE PANA LA 480 KW | H21: 5.87 | I21: =G19*H21 -> 11.74 | J21: 3 | K21: 0 | L21: 0 | M21: =I21-K21-L21 -> 11.74
H22: =0 -> 0 | I22: =G19*H22 -> 0 | J22: 4 | N22: =IF(ISERR(SEARCH("TRA* 82",C19)),IF(Q22+R22+S22=0,0,I22*(Q22/(Q22+R22+S22))),I22) -> 0 | O22: =IF(ISERR(SEARCH("TRA* 82",C19)),IF(Q22+R22+S22=0,0,I22*(R22/(Q22+R22+S22))),0) -> 0 | P22: =IF(ISERR(SEARCH("TRA* 82",C19)),I22-N22-O22,0) -> 0 | Q22: 0 | R22: 0 | S22: 0
A23: ASIMILAT MONTAJ | H23: =H19+H20+H21+H22 -> 96.19 | I23: =I19+I20+I21+I22 -> 192.38 | J23: 5
A24: Arzator gaz automat, progresiv modulant functionând pe gaz Qi=250 kW
B25: 3 | C25: CD11D 02 | D25: M | G25: 2 | H25: 13.69 | I25: =G25*H25 -> 27.38 | J25: 1
D26: =SUBSTITUTE("Sp.mat: 0.00%",".",IF(VALUE("1.2")=1.2,".",","),2) -> Sp.mat: 0.00% | F26: =SUBSTITUTE("Sp.man: 0.00%",".",IF(VALUE("1.2")=1.2,".",","),2) -> Sp.man: 0.00% | G26: =SUBSTITUTE("Sp.uti: 0.00%",".",IF(VALUE("1.2")=1.2,".",","),2) -> Sp.uti: 0.00% | H26: 19.22 | I26: =G25*H26 -> 38.44 | J26: 2
A27: SIST DE COS DE FUM (TIP SCHIEDEL) PREFABR CU TUBULAT DE SAMOTA CU IZOL SI AERIS POSTER D.INT=20 CM | H27: =(1+IF(OR(ISERR(FIND(":",G26)),ISERR(FIND("%",G26))),0,MID(G26,FIND(":",G26)+2,FIND("%",G26)-FIND(":",G26)-2)/100))*0 -> 0 | I27: =G25*H27 -> 0 | J27: 3 | K27: 0 | L27: 0 | M27: =I27-K27-L27 -> 0
H28: =0 -> 0 | I28: =G25*H28 -> 0 | J28: 4 | N28: =IF(ISERR(SEARCH("TRA* 82",C25)),IF(Q28+R28+S28=0,0,I28*(Q28/(Q28+R28+S28))),I28) -> 0 | O28: =IF(ISERR(SEARCH("TRA* 82",C25)),IF(Q28+R28+S28=0,0,I28*(R28/(Q28+R28+S28))),0) -> 0 | P28: =IF(ISERR(SEARCH("TRA* 82",C25)),I28-N28-O28,0) -> 0 | Q28: 0 | R28: 0 | S28: 0
A29: ASIMILAT MONTAJ | H29: =H25+H26+H27+H28 -> 32.91 | I29: =I25+I26+I27+I28 -> 65.82 | J29: 5
A30: canal racordare O200 mm, l=1 m, piese speciale
B31: 4 | C31: CD11G 02 | D31: M | G31: 10 | H31: 23.59 | I31: =G31*H31 -> 235.9 | J31: 1
D32: =SUBSTITUTE("Sp.mat: 0.00%",".",IF(VALUE("1.2")=1.2,".",","),2) -> Sp.mat: 0.00% | F32: =SUBSTITUTE("Sp.man: 0.00%",".",IF(VALUE("1.2")=1.2,".",","),2) -> Sp.man: 0.00% | G32: =SUBSTITUTE("Sp.uti: 0.00%",".",IF(VALUE("1.2")=1.2,".",","),2) -> Sp.uti: 0.00% | H32: 38.44 | I32: =G31*H32 -> 384.4 | J32: 2
A33: SIST DE COS FUM (TIP SCHIEDEL) PREFABR CU TUBULAT DE SAMOTA CU IZOL SI AERIS POSTER D.INT=30 CM | H33: =(1+IF(OR(ISERR(FIND(":",G32)),ISERR(FIND("%",G32))),0,MID(G32,FIND(":",G32)+2,FIND("%",G32)-FIND(":",G32)-2)/100))*0 -> 0 | I33: =G31*H33 -> 0 | J33: 3 | K33: 0 | L33: 0 | M33: =I33-K33-L33 -> 0
H34: =0 -> 0 | I34: =G31*H34 -> 0 | J34: 4 | N34: =IF(ISERR(SEARCH("TRA* 82",C31)),IF(Q34+R34+S34=0,0,I34*(Q34/(Q34+R34+S34))),I34) -> 0 | O34: =IF(ISERR(SEARCH("TRA* 82",C31)),IF(Q34+R34+S34=0,0,I34*(R34/(Q34+R34+S34))),0) -> 0 | P34: =IF(ISERR(SEARCH("TRA* 82",C31)),I34-N34-O34,0) -> 0 | Q34: 0 | R34: 0 | S34: 0
A35: ASIMILAT MONTAJ | H35: =H31+H32+H33+H34 -> 62.03 | I35: =I31+I32+I33+I34 -> 620.3 | J35: 5
A36: Cos de fum O300 mm, H=5 m, piese speciale
B37: 5 | C37: IA17C 99 | D37: BUCATA | G37: 1 | H37: 56.45 | I37: =G37*H37 -> 56.45 | J37: 1
D38: =SUBSTITUTE("Sp.mat: 0.00%",".",IF(VALUE("1.2")=1.2,".",","),2) -> Sp.mat: 0.00% | F38: =SUBSTITUTE("Sp.man: 0.00%",".",IF(VALUE("1.2")=1.2,".",","),2) -> Sp.man: 0.00% | G38: =SUBSTITUTE("Sp.uti: 0.00%",".",IF(VALUE("1.2")=1.2,".",","),2) -> Sp.uti: 0.00% | H38: 56.06 | I38: =G37*H38 -> 56.06 | J38: 2
A39: BOILER VERTICAL MONTAT PE PARDOSEALA CU CAPACIT.DE 1000-2000 L | H39: 0.19 | I39: =G37*H39 -> 0.19 | J39: 3 | K39: 0 | L39: 0.129 | M39: =I39-K39-L39 -> 0.061
H40: =0 -> 0 | I40: =G37*H40 -> 0 | J40: 4 | N40: =IF(ISERR(SEARCH("TRA* 82",C37)),IF(Q40+R40+S40=0,0,I40*(Q40/(Q40+R40+S40))),I40) -> 0 | O40: =IF(ISERR(SEARCH("TRA* 82",C37)),IF(Q40+R40+S40=0,0,I40*(R40/(Q40+R40+S40))),0) -> 0 | P40: =IF(ISERR(SEARCH("TRA* 82",C37)),I40-N40-O40,0) -> 0 | Q40: 0 | R40: 0 | S40: 0
...

Sheet O.01 D.07
A1: Formular F3 | J1: 1
A2: Obiectiv: 01F Construire ansamblu educational compus din scoala, gradinita, cai de circulatie, spatii verzi, terenuri de sport, zone de joaca, corpuri de iluminat, spatiu de parcare, gard incinta,care se va amplasa în partea de nord a Bucurestiului
A3: LISTA_x000D_ cu cantitatile de lucrari pe categorii de lucrari
A4: Obiect: 01 SCOALA
A5: Categorie: 07 INCALZIRE CU CORPURI STATICE (CALORIFERE SI CONVECTOARE DE PARDOSEALA) | I5: [ ron ]
B6: Nr. | C6: Capitol lucrari | D6: U/M | G6: Cantitatea | H6: Pretul unitar | I6: Valoare
B7: Crt. | C7: Simbol | H7: a)materiale
C8: Denumire resursa | H8: b)manopera
C9: Observatii | H9: c)utilaj
C10: Corectii | H10: d)transport
C11: Liste Anexe | H11: Total(a+b+c+d)
B12: 1 | C12: IC36A 99 | D12: M | G12: 1600 | H12: =2701.19/G12 -> 1.6882438 | I12: =G12*H12 -> 2701.19 | J12: 1
D13: =SUBSTITUTE("Sp.mat: 0.00%",".",IF(VALUE("1.2")=1.2,".",","),2) -> Sp.mat: 0.00% | F13: =SUBSTITUTE("Sp.man: 0.00%",".",IF(VALUE("1.2")=1.2,".",","),2) -> Sp.man: 0.00% | G13: =SUBSTITUTE("Sp.uti: 0.00%",".",IF(VALUE("1.2")=1.2,".",","),2) -> Sp.uti: 0.00% | H13: =7688.16/G12 -> 4.8051 | I13: =G12*H13 -> 7688.16 | J13: 2
A14: TV POLIET.ARMATA DE INALTA DENSIT.,POLIPROP.ARMATA /NEARMATA D<20MM MONT.IN COL.LA INST.INC.CENTR. | H14: =(1+IF(OR(ISERR(FIND(":",G13)),ISERR(FIND("%",G13))),0,MID(G13,FIND(":",G13)+2,FIND("%",G13)-FIND(":",G13)-2)/100))*0 -> 0 | I14: =G12*H14 -> 0 | J14: 3 | K14: 0 | L14: 0 | M14: =I14-K14-L14 -> 0
H15: =0 -> 0 | I15: =G12*H15 -> 0 | J15: 4 | N15: =IF(ISERR(SEARCH("TRA* 82",C12)),IF(Q15+R15+S15=0,0,I15*(Q15/(Q15+R15+S15))),I15) -> 0 | O15: =IF(ISERR(SEARCH("TRA* 82",C12)),IF(Q15+R15+S15=0,0,I15*(R15/(Q15+R15+S15))),0) -> 0 | P15: =IF(ISERR(SEARCH("TRA* 82",C12)),I15-N15-O15,0) -> 0 | Q15: 0 | R15: 0 | S15: 0
H16: =H12+H13+H14+H15 -> 6.4933437 | I16: =I12+I13+I14+I15 -> 10389.35 | J16: 5
A17: Teava PPR verde la colac O20x2.8 mm, pentru alimentare calorifere si convectoare de pardoseala
B18: 2 | C18: IZD07A 09 | D18: M | G18: 1600 | H18: =420.03/G18 -> 0.26251875 | I18: =G18*H18 -> 420.03 | J18: 1
D19: =SUBSTITUTE("Sp.mat: 0.00%",".",IF(VALUE("1.2")=1.2,".",","),2) -> Sp.mat: 0.00% | F19: =SUBSTITUTE("Sp.man: 0.00%",".",IF(VALUE("1.2")=1.2,".",","),2) -> Sp.man: 0.00% | G19: =SUBSTITUTE("Sp.uti: 0.00%",".",IF(VALUE("1.2")=1.2,".",","),2) -> Sp.uti: 0.00% | H19: =3075.26/G18 -> 1.9220375 | I19: =G18*H19 -> 3075.26 | J19: 2
A20: IZOLARE TUBURI (TEVI) POLIETILENA DIN PERETI SI PARDOSEALA CU IZOLATIE TIP TUBOLIT S | H20: =49.97/G18 -> 0.03123125 | I20: =G18*H20 -> 49.97 | J20: 3 | K20: 0 | L20: 0 | M20: =I20-K20-L20 -> 49.97
H21: =0 -> 0 | I21: =G18*H21 -> 0 | J21: 4 | N21: =IF(ISERR(SEARCH("TRA* 82",C18)),IF(Q21+R21+S21=0,0,I21*(Q21/(Q21+R21+S21))),I21) -> 0 | O21: =IF(ISERR(SEARCH("TRA* 82",C18)),IF(Q21+R21+S21=0,0,I21*(R21/(Q21+R21+S21))),0) -> 0 | P21: =IF(ISERR(SEARCH("TRA* 82",C18)),I21-N21-O21,0) -> 0 | Q21: 0 | R21: 0 | S21: 0
A22: ASIMILAT MONTAJ IZOLATIE ARMAFLEX | H22: =H18+H19+H20+H21 -> 2.2157875 | I22: =I18+I19+I20+I21 -> 3545.26 | J22: 5
B23: 3 | C23: 7805327 | D23: M | G23: 1600 | H23: =1849.43/G23 -> 1.1558937 | I23: =G23*H23 -> 1849.43 | J23: 1
D24: =SUBSTITUTE("Sp.mat: 0.00%",".",IF(VALUE("1.2")=1.2,".",","),2) -> Sp.mat: 0.00% | F24: =SUBSTITUTE("Sp.man: 0.00%",".",IF(VALUE("1.2")=1.2,".",","),2) -> Sp.man: 0.00% | G24: =SUBSTITUTE("Sp.uti: 0.00%",".",IF(VALUE("1.2")=1.2,".",","),2) -> Sp.uti: 0.00% | H24: =(1+IF(OR(ISERR(FIND(":",F24)),ISERR(FIND("%",F24))),0,MID(F24,FIND(":",F24)+2,FIND("%",F24)-FIND(":",F24)-2)/100))*0 -> 0 | I24: =G23*H24 -> 0 | J24: 2
A25: IZOLATIE ARMAFLEX 9 MM SAU SIMILAR OL 1/2", DN15 | H25: =(1+IF(OR(ISERR(FIND(":",G24)),ISERR(FIND("%",G24))),0,MID(G24,FIND(":",G24)+2,FIND("%",G24)-FIND(":",G24)-2)/100))*0 -> 0 | I25: =G23*H25 -> 0 | J25: 3 | K25: 0 | L25: 0 | M25: =I25-K25-L25 -> 0
H26: =0 -> 0 | I26: =G23*H26 -> 0 | J26: 4 | N26: =IF(ISERR(SEARCH("TRA* 82",C23)),IF(Q26+R26+S26=0,0,I26*(Q26/(Q26+R26+S26))),I26) -> 0 | O26: =IF(ISERR(SEARCH("TRA* 82",C23)),IF(Q26+R26+S26=0,0,I26*(R26/(Q26+R26+S26))),0) -> 0 | P26: =IF(ISERR(SEARCH("TRA* 82",C23)),I26-N26-O26,0) -> 0 | Q26: 0 | R26: 0 | S26: 0
H27: =H23+H24+H25+H26 -> 1.1558937 | I27: =I23+I24+I25+I26 -> 1849.43 | J27: 5
B28: 4 | C28: IC39C 99 | D28: BUCATA | G28: 1 | H28: 194.6 | I28: =G28*H28 -> 194.6 | J28: 1
D29: =SUBSTITUTE("Sp.mat: 0.00%",".",IF(VALUE("1.2")=1.2,".",","),2) -> Sp.mat: 0.00% | F29: =SUBSTITUTE("Sp.man: 0.00%",".",IF(VALUE("1.2")=1.2,".",","),2) -> Sp.man: 0.00% | G29: =SUBSTITUTE("Sp.uti: 0.00%",".",IF(VALUE("1.2")=1.2,".",","),2) -> Sp.uti: 0.00% | H29: 32.03 | I29: =G28*H29 -> 32.03 | J29: 2
A30: DISTRIB/COLECTOR DIN CUPRU D=3/4" PT.RAC.CORPURI I NC.LA INST.INC.CU TV. PLASTIC MONT PE ZID BETON | H30: 0.05 | I30: =G28*H30 -> 0.05 | J30: 3 | K30: 0 | L30: 0.086 | M30: =I30-K30-L30 -> -0.036
H31: =0 -> 0 | I31: =G28*H31 -> 0 | J31: 4 | N31: =IF(ISERR(SEARCH("TRA* 82",C28)),IF(Q31+R31+S31=0,0,I31*(Q31/(Q31+R31+S31))),I31) -> 0 | O31: =IF(ISERR(SEARCH("TRA* 82",C28)),IF(Q31+R31+S31=0,0,I31*(R31/(Q31+R31+S31))),0) -> 0 | P31: =IF(ISERR(SEARCH("TRA* 82",C28)),I31-N31-O31,0) -> 0 | Q31: 0 | R31: 0 | S31: 0
A32: ASIMILAT | H32: =H28+H29+H30+H31 -> 226.68 | I32: =I28+I29+I30+I31 -> 226.68 | J32: 5
A33: Distribuitor/colector complet echipat pentru incalzirea cu calorifere, izolat, cu 3 racorduri,
A34: sistem de legare la automatizare, robineti de sectionare pe
A35: fiecare circuit, senzori de temperatura, robineti automati de aerisire, robineti de golire, caseta
A36: pentru montaj ventilata, cu cadru realizat din tabla
A37: vopsita, cu adancime reglabila, consola.
B38: 5 | C38: IC39D 99 | D38: BUCATA | G38: 1 | H38: 237.19 | I38: =G38*H38 -> 237.19 | J38: 1
D39: =SUBSTITUTE("Sp.mat: 0.00%",".",IF(VALUE("1.2")=1.2,".",","),2) -> Sp.mat: 0.00% | F39: =SUBSTITUTE("Sp.man: 0.00%",".",IF(VALUE("1.2")=1.2,".",","),2) -> Sp.man: 0.00% | G39: =SUBSTITUTE("Sp.uti: 0.00%",".",IF(VALUE("1.2")=1.2,".",","),2) -> Sp.uti: 0.00% | H39: 33.64 | I39: =G38*H39 -> 33.64 | J39: 2
A40: DISTRIB/COLECTOR DIN CUPRU D=1" PT.RAC.CORPURI INC .LA INST.INC.CU TV. PLASTIC MONT PE ZID BETON | H40: 0.05 | I40: =G38*H40 -> 0.05 | J40: 3 | K40: 0 | L40: 0.086 | M40: =I40-K40-L40 -> -0.036
...

Sheet O.01 D.08
A1: Formular F3 | J1: 1
A2: Obiectiv: 01F Construire ansamblu educational compus din scoala, gradinita, cai de circulatie, spatii verzi, terenuri de sport, zone de joaca, corpuri de iluminat, spatiu de parcare, gard incinta,care se va amplasa în partea de nord a Bucurestiului
A3: LISTA_x000D_ cu cantitatile de lucrari pe categorii de lucrari
A4: Obiect: 01 SCOALA
A5: Categorie: 08 INCALZIRE IN PARDOSEALA | I5: [ ron ]
B6: Nr. | C6: Capitol lucrari | D6: U/M | G6: Cantitatea | H6: Pretul unitar | I6: Valoare
B7: Crt. | C7: Simbol | H7: a)materiale
C8: Denumire resursa | H8: b)manopera
C9: Observatii | H9: c)utilaj
C10: Corectii | H10: d)transport
C11: Liste Anexe | H11: Total(a+b+c+d)
B12: 1 | C12: 00612D2A 02 | D12: M | G12: 17000 | H12: =43176.87/G12 -> 2.5398159 | I12: =G12*H12 -> 43176.87 | J12: 1
D13: =SUBSTITUTE("Sp.mat: 0.00%",".",IF(VALUE("1.2")=1.2,".",","),2) -> Sp.mat: 0.00% | F13: =SUBSTITUTE("Sp.man: 0.00%",".",IF(VALUE("1.2")=1.2,".",","),2) -> Sp.man: 0.00% | G13: =SUBSTITUTE("Sp.uti: 0.00%",".",IF(VALUE("1.2")=1.2,".",","),2) -> Sp.uti: 0.00% | H13: =6807.23/G12 -> 0.40042529 | I13: =G12*H13 -> 6807.23 | J13: 2
A14: TEAVA PEX D.16 MM INCALZIRE IN PARDOSEALA, MONTATA PE PLACA CU NUTURI | H14: =(1+IF(OR(ISERR(FIND(":",G13)),ISERR(FIND("%",G13))),0,MID(G13,FIND(":",G13)+2,FIND("%",G13)-FIND(":",G13)-2)/100))*0 -> 0 | I14: =G12*H14 -> 0 | J14: 3 | K14: 0 | L14: 0 | M14: =I14-K14-L14 -> 0
H15: =0 -> 0 | I15: =G12*H15 -> 0 | J15: 4 | N15: =IF(ISERR(SEARCH("TRA* 82",C12)),IF(Q15+R15+S15=0,0,I15*(Q15/(Q15+R15+S15))),I15) -> 0 | O15: =IF(ISERR(SEARCH("TRA* 82",C12)),IF(Q15+R15+S15=0,0,I15*(R15/(Q15+R15+S15))),0) -> 0 | P15: =IF(ISERR(SEARCH("TRA* 82",C12)),I15-N15-O15,0) -> 0 | Q15: 0 | R15: 0 | S15: 0
A16: ASIMILAT | H16: =H12+H13+H14+H15 -> 2.9402412 | I16: =I12+I13+I14+I15 -> 49984.1 | J16: 5
A17: Teava Pe-Xa D17x2 mm neizolata pentru incalzire in pardoseala de tip Rautherm
B18: 2 | C18: 00612D6 02 | D18: BUCATA | G18: 1 | H18: 75.82 | I18: =G18*H18 -> 75.82 | J18: 1
D19: =SUBSTITUTE("Sp.mat: 0.00%",".",IF(VALUE("1.2")=1.2,".",","),2) -> Sp.mat: 0.00% | F19: =SUBSTITUTE("Sp.man: 0.00%",".",IF(VALUE("1.2")=1.2,".",","),2) -> Sp.man: 0.00% | G19: =SUBSTITUTE("Sp.uti: 0.00%",".",IF(VALUE("1.2")=1.2,".",","),2) -> Sp.uti: 0.00% | H19: 10.44 | I19: =G18*H19 -> 10.44 | J19: 2
A20: DISTRIBUITOR SI COLECTOR 2-10 CIRCUITE, INCLUSIV KITUL DE GOLIRE PT PEX INCALZIRE PRIN PARDOSEALA | H20: =(1+IF(OR(ISERR(FIND(":",G19)),ISERR(FIND("%",G19))),0,MID(G19,FIND(":",G19)+2,FIND("%",G19)-FIND(":",G19)-2)/100))*0 -> 0 | I20: =G18*H20 -> 0 | J20: 3 | K20: 0 | L20: 0 | M20: =I20-K20-L20 -> 0
H21: =0 -> 0 | I21: =G18*H21 -> 0 | J21: 4 | N21: =IF(ISERR(SEARCH("TRA* 82",C18)),IF(Q21+R21+S21=0,0,I21*(Q21/(Q21+R21+S21))),I21) -> 0 | O21: =IF(ISERR(SEARCH("TRA* 82",C18)),IF(Q21+R21+S21=0,0,I21*(R21/(Q21+R21+S21))),0) -> 0 | P21: =IF(ISERR(SEARCH("TRA* 82",C18)),I21-N21-O21,0) -> 0 | Q21: 0 | R21: 0 | S21: 0
A22: ASIMILAT | H22: =H18+H19+H20+H21 -> 86.26 | I22: =I18+I19+I20+I21 -> 86.26 | J22: 5
A23: Distribuitor/colector complet echipat pentru incalzirea in pardoseala, izolat, dotat cu pompa si
A24: vana cu 3 cai, clapeta de sens, cu 3 racorduri, electrovane
A25: pentru fiecare circuit, sistem de legare la automatizare, robineti de sectionare pe fiecare circuit,
A26: senzori de temperatura, robineti automati de aerisire,
A27: robineti de golire, caseta pentru montaj ventilata, cu cadru realizat din tabla vopsita, cu
A28: adancime reglabila, consola.
B29: 3 | C29: 00612D6 02 | D29: BUCATA | G29: 3 | H29: 401.78 | I29: =G29*H29 -> 1205.34 | J29: 1
D30: =SUBSTITUTE("Sp.mat: 0.00%",".",IF(VALUE("1.2")=1.2,".",","),2) -> Sp.mat: 0.00% | F30: =SUBSTITUTE("Sp.man: 0.00%",".",IF(VALUE("1.2")=1.2,".",","),2) -> Sp.man: 0.00% | G30: =SUBSTITUTE("Sp.uti: 0.00%",".",IF(VALUE("1.2")=1.2,".",","),2) -> Sp.uti: 0.00% | H30: 10.44 | I30: =G29*H30 -> 31.32 | J30: 2
A31: DISTRIBUITOR SI COLECTOR 2-10 CIRCUITE, INCLUSIV K ITUL DE GOLIRE PT PEX INCALZIRE PRIN PARDOSEALA | H31: =(1+IF(OR(ISERR(FIND(":",G30)),ISERR(FIND("%",G30))),0,MID(G30,FIND(":",G30)+2,FIND("%",G30)-FIND(":",G30)-2)/100))*0 -> 0 | I31: =G29*H31 -> 0 | J31: 3 | K31: 0 | L31: 0 | M31: =I31-K31-L31 -> 0
H32: =0 -> 0 | I32: =G29*H32 -> 0 | J32: 4 | N32: =IF(ISERR(SEARCH("TRA* 82",C29)),IF(Q32+R32+S32=0,0,I32*(Q32/(Q32+R32+S32))),I32) -> 0 | O32: =IF(ISERR(SEARCH("TRA* 82",C29)),IF(Q32+R32+S32=0,0,I32*(R32/(Q32+R32+S32))),0) -> 0 | P32: =IF(ISERR(SEARCH("TRA* 82",C29)),I32-N32-O32,0) -> 0 | Q32: 0 | R32: 0 | S32: 0
A33: ASIMILAT | H33: =H29+H30+H31+H32 -> 412.22 | I33: =I29+I30+I31+I32 -> 1236.66 | J33: 5
A34: Distribuitor/colector complet echipat pentru incalzirea in pardoseala, izolat, dotat cu pompa si
A35: vana cu 3 cai, clapeta de sens, cu 4 racorduri, electrovane
A36: pentru fiecare circuit, sistem de legare la automatizare, robineti de sectionare pe fiecare circuit,
A37: senzori de temperatura, robineti automati de aerisire,
A38: robineti de golire, caseta pentru montaj ventilata, cu cadru realizat din tabla vopsita, cu
A39: adancime reglabila, consola.
B40: 4 | C40: 00612D6 02 | D40: BUCATA | G40: 4 | H40: 433.32 | I40: =G40*H40 -> 1733.28 | J40: 1
...

Sheet O.01 D.09
A1: Formular F3 | J1: 1
A2: Obiectiv: 01F Construire ansamblu educational compus din scoala, gradinita, cai de circulatie, spatii verzi, terenuri de sport, zone de joaca, corpuri de iluminat, spatiu de parcare, gard incinta,care se va amplasa în partea de nord a Bucurestiului
A3: LISTA_x000D_ cu cantitatile de lucrari pe categorii de lucrari
A4: Obiect: 01 SCOALA
A5: Categorie: 09 INSTALATII DE CLIMATIZARE CU VENTILOCONVECTOARE | I5: [ ron ]
B6: Nr. | C6: Capitol lucrari | D6: U/M | G6: Cantitatea | H6: Pretul unitar | I6: Valoare
B7: Crt. | C7: Simbol | H7: a)materiale
C8: Denumire resursa | H8: b)manopera
C9: Observatii | H9: c)utilaj
C10: Corectii | H10: d)transport
C11: Liste Anexe | H11: Total(a+b+c+d)
B12: 1 | C12: IB09A 99 | D12: BUCATA | G12: 64 | H12: =1662.82/G12 -> 25.981562 | I12: =G12*H12 -> 1662.82 | J12: 1
D13: =SUBSTITUTE("Sp.mat: 0.00%",".",IF(VALUE("1.2")=1.2,".",","),2) -> Sp.mat: 0.00% | F13: =SUBSTITUTE("Sp.man: 0.00%",".",IF(VALUE("1.2")=1.2,".",","),2) -> Sp.man: 0.00% | G13: =SUBSTITUTE("Sp.uti: 0.00%",".",IF(VALUE("1.2")=1.2,".",","),2) -> Sp.uti: 0.00% | H13: =1537.63/G12 -> 24.025469 | I13: =G12*H13 -> 1537.63 | J13: 2
A14: AEROTERMA DE PERETE /TAVAN FUNCT.CU APA CALDA ,RACORDATA CU MUFE,AVAND PUTEREA CALORICA < 8,0 KW | H14: 0.07 | I14: =G12*H14 -> 4.48 | J14: 3 | K14: 0 | L14: 8.256 | M14: =I14-K14-L14 -> -3.776
H15: =0 -> 0 | I15: =G12*H15 -> 0 | J15: 4 | N15: =IF(ISERR(SEARCH("TRA* 82",C12)),IF(Q15+R15+S15=0,0,I15*(Q15/(Q15+R15+S15))),I15) -> 0 | O15: =IF(ISERR(SEARCH("TRA* 82",C12)),IF(Q15+R15+S15=0,0,I15*(R15/(Q15+R15+S15))),0) -> 0 | P15: =IF(ISERR(SEARCH("TRA* 82",C12)),I15-N15-O15,0) -> 0 | Q15: 0 | R15: 0 | S15: 0
A16: ASIMILAT MONTAJ VENTILOCONVECTOARE | H16: =H12+H13+H14+H15 -> 50.077031 | I16: =I12+I13+I14+I15 -> 3204.93 | J16: 5
B17: 2 | C17: R000138 | D17: BUCATA | G17: 8 | H17: 845.16 | I17: =G17*H17 -> 6761.28 | J17: 1
D18: =SUBSTITUTE("Sp.mat: 0.00%",".",IF(VALUE("1.2")=1.2,".",","),2) -> Sp.mat: 0.00% | F18: =SUBSTITUTE("Sp.man: 0.00%",".",IF(VALUE("1.2")=1.2,".",","),2) -> Sp.man: 0.00% | G18: =SUBSTITUTE("Sp.uti: 0.00%",".",IF(VALUE("1.2")=1.2,".",","),2) -> Sp.uti: 0.00% | H18: =(1+IF(OR(ISERR(FIND(":",F18)),ISERR(FIND("%",F18))),0,MID(F18,FIND(":",F18)+2,FIND("%",F18)-FIND(":",F18)-2)/100))*0 -> 0 | I18: =G17*H18 -> 0 | J18: 2
A19: VENTILOCONVECTOR 2 TEVI TIP CASETA QR=2,7 KW, ECHIPAT | H19: =(1+IF(OR(ISERR(FIND(":",G18)),ISERR(FIND("%",G18))),0,MID(G18,FIND(":",G18)+2,FIND("%",G18)-FIND(":",G18)-2)/100))*0 -> 0 | I19: =G17*H19 -> 0 | J19: 3 | K19: 0 | L19: 0 | M19: =I19-K19-L19 -> 0
H20: =0 -> 0 | I20: =G17*H20 -> 0 | J20: 4 | N20: =IF(ISERR(SEARCH("TRA* 82",C17)),IF(Q20+R20+S20=0,0,I20*(Q20/(Q20+R20+S20))),I20) -> 0 | O20: =IF(ISERR(SEARCH("TRA* 82",C17)),IF(Q20+R20+S20=0,0,I20*(R20/(Q20+R20+S20))),0) -> 0 | P20: =IF(ISERR(SEARCH("TRA* 82",C17)),I20-N20-O20,0) -> 0 | Q20: 0 | R20: 0 | S20: 0
H21: =H17+H18+H19+H20 -> 845.16 | I21: =I17+I18+I19+I20 -> 6761.28 | J21: 5
B22: 3 | C22: R000140 | D22: BUCATA | G22: 7 | H22: 862.2 | I22: =G22*H22 -> 6035.4 | J22: 1
D23: =SUBSTITUTE("Sp.mat: 0.00%",".",IF(VALUE("1.2")=1.2,".",","),2) -> Sp.mat: 0.00% | F23: =SUBSTITUTE("Sp.man: 0.00%",".",IF(VALUE("1.2")=1.2,".",","),2) -> Sp.man: 0.00% | G23: =SUBSTITUTE("Sp.uti: 0.00%",".",IF(VALUE("1.2")=1.2,".",","),2) -> Sp.uti: 0.00% | H23: =(1+IF(OR(ISERR(FIND(":",F23)),ISERR(FIND("%",F23))),0,MID(F23,FIND(":",F23)+2,FIND("%",F23)-FIND(":",F23)-2)/100))*0 -> 0 | I23: =G22*H23 -> 0 | J23: 2
A24: VENTILOCONVECTOR 2 TEVI TIP CASETA QR=3,3 KW, ECHIPAT | H24: =(1+IF(OR(ISERR(FIND(":",G23)),ISERR(FIND("%",G23))),0,MID(G23,FIND(":",G23)+2,FIND("%",G23)-FIND(":",G23)-2)/100))*0 -> 0 | I24: =G22*H24 -> 0 | J24: 3 | K24: 0 | L24: 0 | M24: =I24-K24-L24 -> 0
